Workbook

Sheet Company Overview
A1: COLGATE-PALMOLIVE
A8: COLGATE REVENUE FROM DIFFERENT PRODUCT PORTFOLIO | G8: COLGATE REVENUE FROM DIFFERENT REGIONS ACROSS GLOBE
H9: Region | I9: Amount | O9: Category | P9: Percentage Holding
B10: Sales | D10: Amount | G10: 1 | H10: North America | I10: 2995 | O10: Promoter and Promoter Group | P10: 0.51
A11: 1 | B11: Oral Care | D11: 9832 | G11: 2 | H11: Latin America | I11: 4778 | O11: Foreign Institutional Investors (FII) | P11: 0.237
A12: 2 | B12: Personal Care | D12: 2830 | G12: 3 | H12: Europe/South Pacific | I12: 3508 | O12: Domestic Institutional Investors (DII) | P12: 0.069
A13: 3 | B13: Home Care | D13: 1900 | G13: 4 | H13: Grater Asia | I13: 3281 | O13: Public (Non-Institutional) | P13: 0.184
A14: 4 | B14: Pet Nutrition | D14: 2172

Sheet Colgate's Operating Divisions
B2: Exhibit 1.1 | E2: COLGATE'S OPERATING DIVISIONS
E3: (2011 AMOUNTS IN $ MILLION)
E4: NET SALES ($) | F4: OPERATING PROFIT ($) | G4: TOTAL ASSETS ($)
B5: Oral,personal and home care
B6: North America | E6: 2995 | F6: 791 | G6: 2288
B7: Latin America | E7: 4778 | F7: 1414 | G7: 3636
B8: Europe/South Pacific | E8: 3508 | F8: 715 | G8: 3555
B9: Greater Asia/Africa | E9: 3281 | F9: 807 | G9: 2069
B10: Total oral,personal and home care | E10: =SUM(E6:E9) -> 14562 | F10: =SUM(F6:F9) -> 3727 | G10: =SUM(G6:G9) -> 11548
B11: Pet nutrition | E11: 2172 | F11: 560 | G11: 1078
B12: Corporate | F12: -446 | G12: 98
B13: Total net sales | E13: =SUM(E10:E12) -> 16734 | F13: =SUM(F10:F12) -> 3841 | G13: =SUM(G10:G12) -> 12724

Sheet Share Price Movement
O1: Interpretation
B18: Colgate Stock Price Growth vs. S&P 500: Fact-Based Interpretation
B20: 1. Overall Trend and Growth
B22: Colgate: Demonstrates a consistent upward trajectory, achieving nearly 60% growth by 2011.
B23: S&P 500: Ends the period with around 20% growth, reflecting slower overall gains and higher volatility.
B25: 2. Key Periods
B26: 2002-2004:
B27: Colgate grows by approximately 10%, slightly outperforming the S&P 500's 5% growth.
B28: 2004-2007:
B29: Colgate grows by roughly 30% during this period, significantly outpacing the S&P 500's 20% growth.
B30: 2008-2009 (Financial Crisis):
B31: S&P 500 declines sharply, losing nearly 40% at its lowest point.
B32: Colgate experiences a milder decline of about 15%, showcasing its resilience.
... B35: S&P 500 recovers more slowly, growing around 25% by 2011, taking longer to regain pre-crisis levels.

Sheet Colgate's Summary Financial
B3: Exhibit 1.3 | D3: COLGATE'S SUMMARY FINANCIAL DATA (in billions, except per share data)
D4: 2011 ($) | E4: 2010 ($) | F4: 2009 ($) | G4: 2008 ($) | H4: 2007 ($) | I4: 2006 ($) | J4: 2005 ($) | K4: 2004 ($) | L4: 2003 ($) | M4: 2002 ($)
B5: Continuing Operations
B6: Net sales | D6: 16.73 | E6: 15.56 | F6: 15.33 | G6: 15.33 | H6: 13.79 | I6: 12.24 | J6: 11.4 | K6: 10.58 | L6: 9.9 | M6: 9.29
B7: Gross Profit | D7: 9.59 | E7: 9.2 | F7: 9.01 | G7: 9.01 | H7: 8.22 | I7: 7.21 | J7: 6.62 | K7: 6.15 | L7: 5.75 | M7: 5.35
B8: Operating Income | D8: 3.84 | E8: 3.49 | F8: 3.62 | G8: 3.33 | H8: 2.96 | I8: 2.57 | J8: 2.37 | K8: 2.2 | L8: 2.14 | M8: 2.02
B9: Net Income | D9: 2.43 | E9: 2.2 | F9: 2.29 | G9: 1.96 | H9: 1.74 | I9: 1.35 | J9: 1.35 | K9: 1.33 | L9: 1.42 | M9: 1.29
B11: Total assets | D11: 12.72 | E11: 11.17 | F11: 11.13 | G11: 9.98 | H11: 10.11 | I11: 9.14 | J11: 8.51 | K11: 8.67 | L11: 7.48 | M11: 7.09
B12: Total liablities | D12: 10.18 | E12: 8.36 | F12: 7.88 | G12: 7.94 | H12: 7.72 | I12: 7.62 | J12: 7.05 | K12: 7.21 | L12: 6.38 | M12: 6.53
B13: Long term debt | D13: 4.43 | E13: 2.82 | F13: 2.82 | G13: 3.59 | H13: 3.22 | I13: 2.72 | J13: 2.92 | K13: 3.09 | L13: 2.68 | M13: 3.21
B14: Shareholder's equity | D14: 2.38 | E14: 2.68 | F14: 3.12 | G14: 1.92 | H14: 2.29 | I14: 1.41 | J14: 1.35 | K14: 1.25 | L14: 0.89 | M14: 0.35
B15: Treasuary stock at cost | D15: 12.81 | E15: 11.31 | F15: 10.48 | G15: 9.7 | H15: 8.9 | I15: 8.07 | J15: 7.58 | K15: 6.97 | L15: 6.5 | M15: 6.15
B17: Basic earnings per share | D17: 4.98 | E17: 4.45 | F17: 4.53 | G17: 3.81 | H17: 3.35 | I17: 2.57 | J17: 2.54 | K17: 2.45 | L17: 2.6 | M17: 2.33
B18: Cash dividends per share | D18: 2.27 | E18: 2.03 | F18: 1.72 | G18: 1.56 | H18: 1.4 | I18: 1.25 | J18: 1.11 | K18: 0.96 | L18: 0.9 | M18: 0.72
B19: Closing stock price | D19: 92.39 | E19: 80.37 | F19: 82.15 | G19: 68.54 | H19: 77.96 | I19: 65.24 | J19: 54.85 | K19: 51.16 | L19: 50.05 | M19: 52.43
B20: Share outstanding (billions) | D20: 0.48 | E20: 0.49 | F20: 0.49 | G20: 0.5 | H20: 0.51 | I20: 0.51 | J20: 0.52 | K20: 0.53 | L20: 0.53 | M20: 0.54

Sheet Balance sheet
B1: COLGATE-PALMOLIVE COMPANY | H1: Exhibit 1.5 | T1: Interpretation
B2: Consolidated Balance Sheets
B3: As of December 31, | K3: The balance sheet of Colgate-Palmolive from 2006 to 2011 reflects key financial trends, business decisions, and external market conditions affecting the company :-
B4: (Dollars in Millions Except Per Share Amounts) | H4: 100
C5: 2011 ($) | D5: 2010 ($) | E5: 2009 ($) | F5: 2008 ($) | G5: 2007 ($) | H5: 2006 ($) | K5: 1. Growth in Total Assets (Financial Strength & Investments)-
B6: Assets | K6: (i) | L6: Total assets increased from $9.1 billion (2006) to $12.7 billion (2011), reflecting a 39% growth over 6 years.
B7: Current Assets
B8: Cash and cash equivalents | C8: 878 | D8: 490 | E8: 600 | F8: 554.9 | G8: 428.7 | H8: 489.5 | K8: (ii) | L8: Major contributors to this growth:
B9: Receivables (net of allowance of $49 and $53, respectively) | C9: 1675 | D9: 1610 | E9: 1626 | F9: 1591.9 | G9: 1680.7 | H9: 1523.2
B10: Inventories | C10: 1327 | D10: 1222 | E10: 1209 | F10: 1197.1 | G10: 1171 | H10: 1008.4 | L10: Increase in goodwill & intangible assets (from $2.9 billion in 2006 to $4 billion in 2011) which suggests acquisitions or brand expansions.
B11: Other current assets | C11: 522 | D11: 408 | E11: 375 | F11: 366.1 | G11: 338.1 | H11: 279.9 | L11: Increase in property, plant & equipment (PPE) (from $2.7 billion in 2006 to $3.6 billion in 2011) which indicates capital investments in production & operations.
B12: Total current assets | C12: =SUM(C8:C11) -> 4402 | D12: =SUM(D8:D11) -> 3730 | E12: =SUM(E8:E11) -> 3810 | F12: =SUM(F8:F11) -> 3710 | G12: =SUM(G8:G11) -> 3618.5 | H12: =SUM(H8:H11) -> 3301 | L12: Total assets grew by 39%, primarily due to increased goodwill, intangible assets, and property investments, indicating expansion efforts.
B13: Property, plant and equipment, net | C13: 3668 | D13: 3693 | E13: 3516 | F13: 3119.5 | G13: 3015.2 | H13: 2696.1
B14: Goodwill, net | C14: 2657 | D14: 2362 | E14: 2302 | F14: 2152 | G14: 2272 | H14: 2081.8
B15: Other intangible assets, net | C15: 1341 | D15: 831 | E15: 821 | F15: 833.5 | G15: 844.8 | H15: 831.1 | K15: 2. Changes in Current Assets (Liquidity & Cash Flow)-
B16: Deferred income taxes | C16: 115 | D16: 84 | K16: (i) | L16: Cash & Cash Equivalents increased significantly from $489 million (2006) to $878 million (2011), which means there is a improved liquidity.
B17: Other assets | C17: 541 | D17: 472 | E17: 685 | F17: 164.3 | G17: 361.5 | H17: 228
B18: Total assets | C18: =SUM(C12:C17) -> 12724 | D18: =SUM(D12:D17) -> 11172 | E18: =SUM(E12:E17) -> 11134 | F18: =SUM(F12:F17) -> 9979.3 | G18: =SUM(G12:G17) -> 10112 | H18: =SUM(H12:H17) -> 9138 | K18: (ii) | L18: Receivables & Inventory also saw a steady rise, indicating growth in sales and operations.
B19: Liablities and shareholder's Equity
B20: Current Liablities | L20: The increase in cash reserves suggests a strong cash flow position, enabling Colgate to reinvest in growth opportunities and manage short-term liabilities.Higher receivables & inventory mean the company is selling more, but it also indicates higher credit sales and potential working capital challenges.
B21: Notes and loans payable | C21: 34 | D21: 48 | E21: 35 | F21: 107.2 | G21: 155.9 | H21: 174.1
B22: Current portion of long term debt | C22: 346 | D22: 561 | E22: 326 | F22: 91 | G22: 138.1 | H22: 776.7
B23: Account payable | C23: 1244 | D23: 1165 | E23: 1172 | F23: 1061.4 | G23: 1066.8 | H23: 1039.7
B24: Accrued income taxes | C24: 392 | D24: 272 | E24: 387 | F24: 272.4 | G24: 262.7 | H24: 161.5
B25: Other accruals | C25: 1700 | D25: 1682 | E25: 1679 | F25: 1421.3 | G25: 1539.2 | H25: 1317.1
B26: Total current liablities | C26: =SUM(C21:C25) -> 3716 | D26: =SUM(D21:D25) -> 3728 | E26: =SUM(E21:E25) -> 3599 | F26: =SUM(F21:F25) -> 2953.3 | G26: =SUM(G21:G25) -> 3162.7 | H26: =SUM(H21:H25) -> 3469.1
B27: Long term debt | C27: 4430 | D27: 2815 | E27: 2821 | F27: 3585.3 | G27: 3221.9 | H27: 2720.4 | K27: 3. Increase in Liabilities (Debt & Financial Leverage)
B28: Deferred income taxes | C28: 252 | D28: 108 | E28: 82 | F28: 81.9 | G28: 264.1 | H28: 309.9
B29: Other liablities | C29: 1785 | D29: 1704 | E29: 1375 | F29: 1436.7 | G29: 1177.1 | H29: 1227.7 | K29: (i) | L29: Total liabilities rose from $7.7 billion (2006) to $10.1 billion (2011), showing an increase of 31%.
B30: Total liablities | C30: =SUM(C26:C29) -> 10183 | D30: =SUM(D26:D29) -> 8355 | E30: =SUM(E26:E29) -> 7877 | F30: =SUM(F26:F29) -> 8057.2 | G30: =SUM(G26:G29) -> 7825.8 | H30: =SUM(H26:H29) -> 7727.1
B31: Commitments and contingent liablities | K31: (ii) | L31: Long-term debt surged from $2.7 billion (2006) to $4.4 billion (2011).
B32: Shareholder's Equity
B33: Preference stock | C33: 0 | D33: 0 | E33: 169 | F33: 181 | G33: 197.5 | H33: 222.7 | L33: The rising debt suggests that Colgate has been leveraging external funding for expansion, acquisitions, or new market entries. While debt increases financial risk, it also indicates confidence in future revenue growth.
B34: Common stock par value(2,000,000,000 shares authorized, 732,853,180 shares issued) | C34: 733 | D34: 733 | E34: 733 | F34: 732.9 | G34: 732.9 | H34: 732.9
B35: Additional paid-in capital | C35: 1336 | D35: 1132 | E35: 1764 | F35: 1609.7 | G35: 1517.7 | H35: 1218.1
B36: Retained earming | C36: 15649 | D36: 14329 | E36: 13157 | F36: 11759.5 | G36: 10627.5 | H36: 9643.7
B37: Accumulated other comprehensive income( loss) | C37: -2475 | D37: -2115 | E37: -2096 | F37: -2477.3 | G37: -1666.8 | H37: -2081.2
C38: =SUM(C33:C37) -> 15243 | D38: =SUM(D33:D37) -> 14079 | E38: =SUM(E33:E37) -> 13727 | F38: =SUM(F33:F37) -> 11805.8 | G38: =SUM(G33:G37) -> 11408.8 | H38: =SUM(H33:H37) -> 9736.2
B39: Unearned compensation | C39: -60 | D39: -99 | E39: -133 | F39: -187 | G39: -218 | H39: -251.4
B40: Treasury, stock, at cost | C40: -12808 | D40: -11305 | E40: -10478 | F40: -9696.7 | G40: -8903.7 | H40: -8073.9 | K40: 4. Shareholder’s Equity Trends (Stock Buybacks & Profit Retention)
...

Sheet Income statement
P1: Interpretation
B2: COLGATE-PALMOLIVE COMPANY
B3: Consolidated Statement of Income | I3: Exhibit 1.6 | K3: Colgate-Palmolive’s income statement from 2006 to 2011 reflects strong business growth, increasing profitability, and effective cost management strategies :-
B4: For the year ended December 31,
B5: (Dollars in Millions Except Per Share Amounts) | K5: 1. Revenue Growth & Market Expansion :-
C6: 2011 ($) | D6: 2010 ($) | E6: 2009 ($) | F6: 2008 ($) | G6: 2007 ($) | H6: 2006 ($) | K6: Colgate’s net sales grew from $12.2 billion in 2006 to $16.7 billion in 2011, a 37% increase. This steady growth indicates:
B7: Net sales | C7: 16734 | D7: 15564 | E7: 15327 | F7: 15329.9 | G7: 13789.7 | H7: 12237.7
B8: Cost of sales | C8: 7144 | D8: 6360 | E8: 6319 | F8: 6703.5 | G8: 6042.3 | H8: 5536.1 | L8: Strong demand for its products globally – possibly through aggressive marketing, brand loyalty, and an expanding product portfolio.
B9: Gross Profit | C9: =C7-C8 -> 9590 | D9: =D7-D8 -> 9204 | E9: =E7-E8 -> 9008 | F9: =F7-F8 -> 8626.4 | G9: =G7-G8 -> 7747.4 | H9: =H7-H8 -> 6701.6
B10: Selling, general and administrative expenses | C10: 5758 | D10: 5414 | E10: 5282 | F10: 5422.3 | G10: 4973 | H10: 4355.2 | L10: Geographical expansion – Colgate has a dominant presence in emerging markets, contributing to its rising sales.
B11: Other(income) expense, net | C11: -9 | D11: 301 | E11: 111 | F11: 183.4 | G11: 121.3 | H11: 185.9
B12: Operating Profit | C12: =C9-C10-C11 -> 3841 | D12: =D9-D10-D11 -> 3489 | E12: =E9-E10-E11 -> 3615 | F12: =F9-F10-F11 -> 3020.7 | G12: =G9-G10-G11 -> 2653.1 | H12: =H9-H10-H11 -> 2160.5 | L12: Pricing strategies & product innovation – Incremental increases in revenue suggest the company likely adjusted prices and introduced new products to sustain market share.
B13: Interest expense, net | C13: 52 | D13: 59 | E13: 77 | F13: 95.6 | G13: 156.6 | H13: 158.7
B14: Income Before income taxes | C14: =C12-C13 -> 3789 | D14: =D12-D13 -> 3430 | E14: =E12-E13 -> 3538 | F14: =F12-F13 -> 2925.1 | G14: =G12-G13 -> 2496.5 | H14: =H12-H13 -> 2001.8 | K14: 2. Cost Management & Gross Profit Trends :-
B15: Provision for income taxes | C15: 1235 | D15: 1117 | E15: 1141 | F15: 967.9 | G15: 759.1 | H15: 648.4
B16: Net income including noncontrolling interests | C16: =C14-C15 -> 2554 | D16: =D14-D15 -> 2313 | E16: =E14-E15 -> 2397 | F16: =F14-F15 -> 1957.2 | G16: =G14-G15 -> 1737.4 | H16: =H14-H15 -> 1353.4 | L16: Cost of Sales (COGS) rose from $5.5 billion (2006) to $7.1 billion (2011), but gross profit also increased from $6.7 billion to $9.5 billion.
B17: Net income attributable to noncontrolling interests | C17: 123 | D17: 1 | E17: 106
B18: Net income attributable to Colgate-Palmolive Company | C18: =C16-C17 -> 2431 | D18: =D16-D17 -> 2312 | E18: =E16-E17 -> 2291 | F18: =F16-F17 -> 1957.2 | G18: =G16-G17 -> 1737.4 | H18: =H16-H17 -> 1353.4 | L18: Gross Margin remained strong (~57% in 2011), meaning Colgate successfully controlled raw material costs while maintaining premium pricing.
B19: Earning per common share, basic | C19: 4.98 | D19: 4.45 | E19: 4.53 | F19: 3.81 | G19: 3.35 | H19: 2.57
B20: Earning per common share, diluted | C20: 4.94 | D20: 4.31 | E20: 4.37 | F20: 3.66 | G20: 3.2 | H20: 2.46 | L20: The company likely optimized its supply chain, reduced wastage, or negotiated better deals with suppliers to keep costs in check.
K22: 3. Operating Profit & Expense Management :-
L24: Selling, General & Administrative Expenses (SG&A) rose from $4.3 billion in 2006 to $5.7 billion in 2011. However, this increase is proportional to revenue growth.
L26: Despite higher expenses, operating profit surged from $2.1 billion to $3.8 billion, showing operational efficiency.
L28: The drop in ‘Other Expenses’ from $301 million (2010) to -$9 million (2011) indicates potential gains from investments, asset sales, or foreign exchange benefits.
K30: 4. Declining Interest Expenses & Strong Financial Position :-
L32: Interest expense dropped from $158 million (2006) to just $52 million (2011), indicating that colgate has reduced its debt burden or refinanced at lower interest rates.
L34: A lower interest expense means the company is spending less on financing costs and more on growth initiatives.
K36: 5. Net Profit & Shareholder Returns :-
L38: Net income increased significantly from $1.35 billion in 2006 to $2.55 billion in 2011 (88% growth).
L40: Earnings per Share (EPS) (Basic) jumped from $2.57 in 2006 to $4.98 in 2011 which indicates two things, strong profitability and revenue expansion and Share buybacks, reducing the number of outstanding shares and increasing EPS.
L42: Higher EPS and net profit show that Colgate is generating strong returns for shareholders.

Sheet P&L (Horizontal)
A1: Exhibit 1.10 | B1: COLGATE-PALMOLIVE COMPANY | L1: Key observation
B2: Consolidated Statement of Income Statement
B3: For the year ended December 31, | I3: 1. Net Sales Growth: Increased from $15,564 million to $16,734 million which is 7.52% increase.This moderate growth in sales indicates an increase in demand or effective pricing strategies. Factors like new product launches, expanded markets, or strong brand presence might have contributed.
B4: (Dollars in Millions Except Per Share Amounts)
C5: HORIZONTAL ANALYSIS
C6: 2011 ($) | D6: 2010 ($) | E6: 2011 ($) | F6: 2010 ($) | G6: 100
B7: Net sales | C7: 16734 | D7: 15564 | E7: =C7/D7*$G$6 -> 107.51735 | F7: =D7/D7*$G$6 -> 100
B8: Cost of sales | C8: 7144 | D8: 6360 | E8: =C8/D8*$G$6 -> 112.32704 | F8: =D8/D8*$G$6 -> 100
B9: Gross Profit | C9: =C7-C8 -> 9590 | D9: =D7-D8 -> 9204 | E9: =C9/D9*$G$6 -> 104.19383 | F9: =D9/D9*$G$6 -> 100
B10: Selling, general and administrative expenses | C10: 5758 | D10: 5414 | E10: =C10/D10*$G$6 -> 106.3539 | F10: =D10/D10*$G$6 -> 100 | I10: 2. Cost of Sales: There is a 12.33% increase in the cost of sales, which also increased at a faster rate than net sales. This suggests rising production costs, raw material price hikes, or supply chain inefficiencies.
B11: Other(income) expense, net | C11: -9 | D11: 301 | E11: =C11/D11*$G$6 -> -2.9900332 | F11: =D11/D11*$G$6 -> 100
B12: Operating Profit | C12: =C9-C10-C11 -> 3841 | D12: =D9-D10-D11 -> 3489 | E12: =C12/D12*$G$6 -> 110.08885 | F12: =D12/D12*$G$6 -> 100
B13: Interest expense, net | C13: 52 | D13: 59 | E13: =C13/D13*$G$6 -> 88.135593 | F13: =D13/D13*$G$6 -> 100
B14: Income Before income taxes | C14: =C12-C13 -> 3789 | D14: =D12-D13 -> 3430 | E14: =C14/D14*$G$6 -> 110.46647 | F14: =D14/D14*$G$6 -> 100
B15: Provision for income taxes | C15: 1235 | D15: 1117 | E15: =C15/D15*$G$6 -> 110.56401 | F15: =D15/D15*$G$6 -> 100 | I15: 3.Gross Profit: There is a 4.19% increase in the gross profit. This increase is due to growth in the net sales, product mix shifts and operational efficiencies. But there is a decline in the gross margin percentage due to the rising costs.
B16: Net income including noncontrolling interests | C16: =C14-C15 -> 2554 | D16: =D14-D15 -> 2313 | E16: =C16/D16*$G$6 -> 110.41937 | F16: =D16/D16*$G$6 -> 100
B17: Net income attributable to noncontrolling interests | C17: 123 | D17: 110 | E17: =C17/D17*$G$6 -> 111.81818 | F17: =D17/D17*$G$6 -> 100
B18: Net income attributable to Colgate-Palmolive Company | C18: =C16-C17 -> 2431 | D18: =D16-D17 -> 2203 | E18: =C18/D18*$G$6 -> 110.34952 | F18: =D18/D18*$G$6 -> 100
B19: Earning per common share, basic | C19: 4.98 | D19: 4.45
B20: Earning per common share, diluted | C20: 4.94 | D20: 4.31 | I20: 4. Interest Expense: There is 11.86% decrease in the interest expenses. This could be because that company may have paid down existing debt, reducing the total outstanding loan amount. This is a positive indicator which suggests improved debt management and lower borrowing rates.
I25: 5. Net Income : There is a 10.35% increase in the net income as the net sales increased, strong operating profit, and reduction in the interest income.This reflects efficient cost control and operational improvements, offsetting higher cost of sales.
I30: 6. Earning Per Share :The increase in both basic and diluted EPS indicates that Colgate-Palmolive not only grew its profits but also managed its capital structure efficiently, enhancing shareholder value. This is a positive signal for investors, reflecting both strong operational performance and strategic financial management.

Sheet P&L (Vertical)
B1: Exhibit 1.12 | L1: Key Observations and Interpretation
B2: COLGATE-PALMOLIVE COMPANY
B3: Consolidated Statement of Income
B4: For the year ended December 31, | E4: VERTICAL ANALYSIS | I4: 1. Revenue Growth & Cost of Sales Impact :-
B5: (Dollars in Millions Except Per Share Amounts) | E5: 100
B6: Particular | C6: 2011 ($) | D6: 2010 ($) | E6: 2011 ($) | F6: 2010 ($) | I6: Net sales increased from $15.56 billion (2010) to $16.73 billion (2011), a 7.5% growth.
B7: Net sales | C7: 16734 | D7: 15564 | E7: =C7/$C$7*$E$5 -> 100 | F7: =D7/$D$7*$E$5 -> 100 | I7: Cost of sales as a percentage of revenue increased from 40.86% (2010) to 42.69% (2011), meaning production costs rose at a faster rate than sales.
B8: Cost of sales | C8: 7144 | D8: 6360 | E8: =C8/$C$7*$E$5 -> 42.691526 | F8: =D8/$D$7*$E$5 -> 40.863531
B9: Gross Profit | C9: =C7-C8 -> 9590 | D9: =D7-D8 -> 9204 | E9: =C9/$C$7*$E$5 -> 57.308474 | F9: =D9/$D$7*$E$5 -> 59.136469 | I9: Business Impact:
B10: Selling, general and administrative expenses | C10: 5758 | D10: 5414 | E10: =C10/$C$7*$E$5 -> 34.408988 | F10: =D10/$D$7*$E$5 -> 34.785402 | I10: Higher raw material prices, supply chain costs, or changes in product mix may have increased production expenses.
B11: Other(income) expense, net | C11: -9 | D11: 301 | E11: =C11/$C$7*$E$5 -> -0.053782718 | F11: =D11/$D$7*$E$5 -> 1.9339501 | I11: Despite revenue growth, the decline in gross margin (from 59.14% to 57.31%) suggests pressure on profit generation from direct costs.
B12: Operating Profit | C12: =C9-C10-C11 -> 3841 | D12: =D9-D10-D11 -> 3489 | E12: =C12/$C$7*$E$5 -> 22.953269 | F12: =D12/$D$7*$E$5 -> 22.417116
B13: Interest expense, net | C13: 52 | D13: 59 | E13: =C13/$C$7*$E$5 -> 0.31074459 | F13: =D13/$D$7*$E$5 -> 0.37907993 | I13: 2. Selling, General & Administrative (SG&A) Expenses :-
B14: Income Before income taxes | C14: =C12-C13 -> 3789 | D14: =D12-D13 -> 3430 | E14: =C14/$C$7*$E$5 -> 22.642524 | F14: =D14/$D$7*$E$5 -> 22.038036
B15: Provision for income taxes | C15: 1235 | D15: 1117 | E15: =C15/$C$7*$E$5 -> 7.3801841 | F15: =D15/$D$7*$E$5 -> 7.1768183 | I15: SG&A expenses remained stable at 34% of net sales (34.79% in 2010 vs. 34.41% in 2011).
B16: Net income including noncontrolling interests | C16: =C14-C15 -> 2554 | D16: =D14-D15 -> 2313 | E16: =C16/$C$7*$E$5 -> 15.26234 | F16: =D16/$D$7*$E$5 -> 14.861218 | I16: This indicates consistent operational efficiency in managing marketing, distribution, and administrative costs.
B17: Net income attributable to noncontrolling interests | C17: 123 | D17: 110 | E17: =C17/$C$7*$E$5 -> 0.73503048 | F17: =D17/$D$7*$E$5 -> 0.70675919
B18: Net income attributable to Colgate-Palmolive Company | C18: =C16-C17 -> 2431 | D18: =D16-D17 -> 2203 | E18: =C18/$C$7*$E$5 -> 14.52731 | F18: =D18/$D$7*$E$5 -> 14.154459 | I18: Business Impact:
B19: Earning per common share, basic | C19: 4.98 | D19: 4.45 | I19: The company controlled its overhead expenses despite increased sales.
B20: Earning per common share, diluted | C20: 4.94 | D20: 4.31 | I20: Stable SG&A expenses suggest Colgate invested in advertising, R&D, and operational expansions without significantly increasing costs.
I22: 3. Operating Profit & Efficiency Gains :-
I24: Operating profit margin slightly improved from 22.42% (2010) to 22.95% (2011).
I25: This means Colgate managed to offset some of the rising production costs with operational efficiency.
I27: Key Driver:
I28: Lower Other expenses (-0.05% in 2011 vs. 1.93% in 2010) likely contributed to better margins.
I29: Gains from asset sales, reduced non-core business expenses, or one-time financial adjustments could be the possible reasons.
I31: 4. Net Income & Profitability Trends :-
I33: Income before taxes increased from 22.04% (2010) to 22.64% (2011), reflecting better pre-tax profitability.
I34: Net income margin improved from 14.15% (2010) to 14.53% (2011), meaning Colgate retained more profit per dollar of sales.
I36: Key Profitability Drivers:
I38: Sales growth boosted total earnings.
I39: Lower other expenses improved operational efficiency
... I45: A higher EPS makes Colgate more attractive to investors, reinforcing confidence in its long-term profitability.

Sheet BS (Ver & Horz)
B1: Exhibit 1.13 | F1: Colgate's Common size Balance Sheet | M1: Interpretation of vertical analysis | Z1: Interpretation of horizontal analysis
B2: COLGATE-PALMOLIVE COMPANY
B3: Consolidated Balance Sheets | M3: Assets: | Z3: Assets:
B4: As of December 31,
B5: (Dollars in Millions Except Per Share Amounts) | M5: Current Assets increased from 33.39% (2010) to 34.60% (2011) of total assets. This increased due to cash and cash equivalents which rose significantly (from 4.39% to 6.90%) due to better cash management, possibly from strong operational cash flows. | Z5: Total assets increased by 13.89%, reflecting the company's growth initiatives. This growth was largely fueled by a remarkable 179.18% surge in cash and cash equivalents, indicating robust operational cash flows, potential asset sales, or reduced short-term investments. Additionally, the 161.37% increase in other intangible assets and a 12.49% rise in goodwill suggest that Colgate engaged in significant acquisitions, likely aiming to strengthen its brand portfolio and expand market reach. However, there was a slight decline in property, plant, and equipment (-0.68%), which could indicate minimal new capital investments or higher depreciation, raising concerns about the sustainability of physical asset growth.
C6: 100 | F6: Vertical Analysis | I6: Horizontal Analysis
C7: 2011 ($) | D7: 2010 ($) | F7: 2011 ($) | G7: 2010 ($) | I7: 2011 ($) | J7: 2010 ($)
B8: Assets
B9: Current Assets
B10: Cash and cash equivalents | C10: 878 | D10: 490 | F10: =C10/$C$21*$C$6 -> 6.9003458 | G10: =D10/$D$21*$C$6 -> 4.3859649 | I10: =C10/D10*$C$6 -> 179.18367 | J10: =D10/D10*$C$6 -> 100
B11: Receivables (net of allowance of $49 and $53, respectivelyInventories | C11: 1675 | D11: 1610 | F11: =C11/$C$21*$C$6 -> 13.164099 | G11: =D11/$D$21*$C$6 -> 14.411028 | I11: =C11/D11*$C$6 -> 104.03727 | J11: =D11/D11*$C$6 -> 100
B12: Inventories | C12: 1327 | D12: 1222 | F12: =C12/$C$21*$C$6 -> 10.42911 | G12: =D12/$D$21*$C$6 -> 10.938059 | I12: =C12/D12*$C$6 -> 108.59247 | J12: =D12/D12*$C$6 -> 100 | M12: Fixed Assets decreased slightly as a percentage of total assets (66.61% to 65.40%). This indicate either lower capital investments or higher growth in current assets relative to fixed assets.
B13: Other current assets | C13: 522 | D13: 408 | F13: =C13/$C$21*$C$6 -> 4.1024835 | G13: =D13/$D$21*$C$6 -> 3.6519871 | I13: =C13/D13*$C$6 -> 127.94118 | J13: =D13/D13*$C$6 -> 100
B14: Total current assets | C14: =SUM(C10:C13) -> 4402 | D14: =SUM(D10:D13) -> 3730 | F14: =C14/$C$21*$C$6 -> 34.596039 | G14: =D14/$D$21*$C$6 -> 33.387039 | I14: =C14/D14*$C$6 -> 118.01609 | J14: =D14/D14*$C$6 -> 100
B15: Property, plant and equipment, net | C15: 3668 | D15: 3693 | F15: =C15/$C$21*$C$6 -> 28.827413 | G15: =D15/$D$21*$C$6 -> 33.055854 | I15: =C15/D15*$C$6 -> 99.323044 | J15: =D15/D15*$C$6 -> 100
B16: Goodwill, net | C16: 2657 | D16: 2362 | F16: =C16/$C$21*$C$6 -> 20.881798 | G16: =D16/$D$21*$C$6 -> 21.142141 | I16: =C16/D16*$C$6 -> 112.48942 | J16: =D16/D16*$C$6 -> 100 | M16: Intangible Assets (Goodwill & Other Intangibles) rose from 28.58% to 31.42% which means the brand value has also increased.
B17: Other intangible assets, net | C17: 1341 | D17: 831 | F17: =C17/$C$21*$C$6 -> 10.539139 | G17: =D17/$D$21*$C$6 -> 7.4382385 | I17: =C17/D17*$C$6 -> 161.37184 | J17: =D17/D17*$C$6 -> 100 | Z17: Liabilities:
B18: Deferred income taxes | C18: 115 | D18: 84 | F18: =C18/$C$21*$C$6 -> 0.90380384 | G18: =D18/$D$21*$C$6 -> 0.7518797 | I18: =C18/D18*$C$6 -> 136.90476 | J18: =D18/D18*$C$6 -> 100
B19: Other assets | C19: 541 | D19: 472 | F19: =C19/$C$21*$C$6 -> 4.2518076 | G19: =D19/$D$21*$C$6 -> 4.2248478 | I19: =C19/D19*$C$6 -> 114.61864 | J19: =D19/D19*$C$6 -> 100 | M19: Liabilities: | Z19: Total liabilities jumped by 21.88%, outpacing asset growth and indicating a heavier reliance on debt. The most striking change was the 57.37% increase in long-term debt, which indicates that Colgate financed its acquisitions and expansion through debt rather than equity. While leveraging debt can amplify growth during prosperous times, it also increases financial risk, especially if earnings do not grow proportionally. The short-term notes and loans payable decreased by 29.17%, reflecting a strategic shift toward long-term financing, which might reduce immediate liquidity pressures but increases long-term obligations.
B20: Total fixed asset | C20: =SUM(C15:C19) -> 8322 | D20: =SUM(D15:D19) -> 7442 | F20: =C20/$C$21*$C$6 -> 65.403961 | G20: =D20/$D$21*$C$6 -> 66.612961 | I20: =C20/D20*$C$6 -> 111.82478 | J20: =D20/D20*$C$6 -> 100
B21: Total assets | C21: =SUM(C14:C19) -> 12724 | D21: =SUM(D14:D19) -> 11172 | F21: =C21/$C$21*$C$6 -> 100 | G21: =D21/$D$21*$C$6 -> 100 | I21: =C21/D21*C6 -> 113.89187 | J21: =D21/D21*C6 -> 100 | M21: Total Liabilities rose from 74.79% (2010) to 80.03% (2011), indicating a shift towards a more leveraged capital structure. Current Liabilities decreased slightly as a percentage (33.37% to 29.20%), showing improved short-term liquidity. Long-Term Debt increased significantly (25.20% to 34.82%), suggesting reliance on long-term financing, possibly for acquisitions or expansion. This increase is due to significant rise in long term debts of about 9.62% and increase in the deferred income taxes.
B22: Liablities and shareholder's Equity | F22: =C22/$C$21*$C$6 -> 0 | G22: =D22/$D$21*$C$6 -> 0
B23: Current Liablities | F23: =C23/$C$21*$C$6 -> 0 | G23: =D23/$D$21*$C$6 -> 0
B24: Notes and loans payable | C24: 34 | D24: 48 | F24: =C24/$C$21*$C$6 -> 0.26721157 | G24: =D24/$D$21*$C$6 -> 0.42964554 | I24: =C24/D24*$C$6 -> 70.833333 | J24: =D24/D24*$C$6 -> 100
B25: Current portion of long term debt | C25: 346 | D25: 561 | F25: =C25/$C$21*$C$6 -> 2.7192707 | G25: =D25/$D$21*$C$6 -> 5.0214823 | I25: =C25/D25*$C$6 -> 61.675579 | J25: =D25/D25*$C$6 -> 100
B26: Account payable | C26: 1244 | D26: 1165 | F26: =C26/$C$21*$C$6 -> 9.7767997 | G26: =D26/$D$21*$C$6 -> 10.427855 | I26: =C26/D26*$C$6 -> 106.78112 | J26: =D26/D26*$C$6 -> 100
B27: Accrued income taxes | C27: 392 | D27: 272 | F27: =C27/$C$21*$C$6 -> 3.0807922 | G27: =D27/$D$21*$C$6 -> 2.4346581 | I27: =C27/D27*$C$6 -> 144.11765 | J27: =D27/D27*$C$6 -> 100
B28: Other accruals | C28: 1700 | D28: 1682 | F28: =C28/$C$21*$C$6 -> 13.360578 | G28: =D28/$D$21*$C$6 -> 15.055496 | I28: =C28/D28*$C$6 -> 101.07015 | J28: =D28/D28*$C$6 -> 100
B29: Total current liablities | C29: =SUM(C24:C28) -> 3716 | D29: =SUM(D24:D28) -> 3728 | F29: =C29/$C$21*$C$6 -> 29.204653 | G29: =D29/$D$21*$C$6 -> 33.369137 | I29: =C29/D29*$C$6 -> 99.678112 | J29: =D29/D29*$C$6 -> 100
B30: Long term debt | C30: 4430 | D30: 2815 | F30: =C30/$C$21*$C$6 -> 34.816096 | G30: =D30/$D$21*$C$6 -> 25.196921 | I30: =C30/D30*$C$6 -> 157.37123 | J30: =D30/D30*$C$6 -> 100
B31: Deferred income taxes | C31: 252 | D31: 108 | F31: =C31/$C$21*$C$6 -> 1.9805093 | G31: =D31/$D$21*$C$6 -> 0.96670247 | I31: =C31/D31*$C$6 -> 233.33333 | J31: =D31/D31*$C$6 -> 100 | M31: Shareholders' Equity: | Z31: Shareholders' Equity:
B32: Other liablities | C32: 1785 | D32: 1704 | F32: =C32/$C$21*$C$6 -> 14.028607 | G32: =D32/$D$21*$C$6 -> 15.252417 | I32: =C32/D32*$C$6 -> 104.75352 | J32: =D32/D32*$C$6 -> 100
B33: Total liablities | C33: =SUM(C29:C32) -> 10183 | D33: =SUM(D29:D32) -> 8355 | F33: =C33/$C$21*$C$6 -> 80.029865 | G33: =D33/$D$21*$C$6 -> 74.785177 | I33: =C33/D33*C6 -> 121.87911 | J33: =D33/D33*C6 -> 100 | M33: Equity declined from 25.21% (2010) to 19.97% (2011) of total assets. This decline in equity is due to increase in retained earnings , reflecting profitability, but this was offset by higher treasury stock and increased accumulated losses in other comprehensive income. Treasury Stock impact grew from -101.19% to -100.66%, indicating aggressive share repurchase activities, which reduce equity. | Z33: Shareholders’ equity declined by 9.80%, despite the company’s growth in assets and profits. This decline is primarily attributed to aggressive share buybacks, as evidenced by a 13.30% increase in treasury stock, which reduces outstanding shares and enhances earnings per share (EPS) but diminishes overall equity.
B34: Commitments and contingent liablities
B35: Shareholder's Equity
B36: Preference stock
B37: Common stock par value(2,000,000,000 shares authorized, 732,853,180 shares issued) | C37: 733 | D37: 733 | F37: =C37/$C$21*$C$6 -> 5.7607671 | G37: =D37/$D$21*$C$6 -> 6.5610455 | I37: =C37/D37*$C$6 -> 100 | J37: =D37/D37*$C$6 -> 100
B38: Additional paid-in capital | C38: 1336 | D38: 1132 | F38: =C38/$C$21*$C$6 -> 10.499843 | G38: =D38/$D$21*$C$6 -> 10.132474 | I38: =C38/D38*$C$6 -> 118.0212 | J38: =D38/D38*$C$6 -> 100
B39: Retained earming | C39: 15649 | D39: 14329 | F39: =C39/$C$21*$C$6 -> 122.98805 | G39: =D39/$D$21*$C$6 -> 128.25815 | I39: =C39/D39*$C$6 -> 109.21209 | J39: =D39/D39*$C$6 -> 100
B40: Accumulated other comprehensive income( loss) | C40: -2475 | D40: -2115 | F40: =C40/$C$21*$C$6 -> -19.45143 | G40: =D40/$D$21*$C$6 -> -18.931257 | I40: =C40/D40*$C$6 -> 117.02128 | J40: =D40/D40*$C$6 -> 100
...

Sheet Ratios
B1: COLGATE PALMOLIVE (INDIA) Ltd. | J1: Interpretation
B3: Particulars | D3: Ratio Analysis | H3: 1. Liquidity ratio | J3: The current ratio has increased which suggests improved short-term financial health. The company now has ₹1.18 in current assets for every ₹1 in liabilities, up from ₹1.00. This indicates better working capital management and a stronger liquidity position. The quick ratio shows the company is better at covering short-term liabilities without relying on inventory which indicates enhanced liquidity efficiency.
D4: Ratio Formula | E4: Year | F4: Year
E5: 2011 | F5: 2010
B6: Liquidity | C6: Current Ratio | D6: Current Asset/Current Liablities | E6: ='BS (Ver & Horz)'!C14/'BS (Ver & Horz)'!C29 -> 1.1846071 | F6: ='BS (Ver & Horz)'!D14/'BS (Ver & Horz)'!D29 -> 1.0005365
C7: Quick Ratio | D7: Quick Asset/Current Liablities | E7: =('BS (Ver & Horz)'!C14-'BS (Ver & Horz)'!C12)/'BS (Ver & Horz)'!C29 -> 0.82750269 | F7: =('BS (Ver & Horz)'!D14-'BS (Ver & Horz)'!D12)/'BS (Ver & Horz)'!D29 -> 0.67274678
B8: Probability | C8: Net Profit Margin Ratio | D8: EAT/Total Income | E8: ='P&L (Vertical)'!C18/'P&L (Vertical)'!C7 -> 0.1452731 | F8: ='P&L (Vertical)'!D18/'P&L (Vertical)'!D7 -> 0.14154459
C9: Gross Profit Margin | D9: Gross Profit/Revenue from operation | E9: ='P&L (Vertical)'!C9/'P&L (Vertical)'!C7 -> 0.57308474 | F9: ='P&L (Vertical)'!D9/'P&L (Vertical)'!D7 -> 0.59136469
C10: Return on Asset | D10: EAT/Average Total Asset | E10: ='P&L (Vertical)'!C18/'BS (Ver & Horz)'!C21 -> 0.19105627 | F10: ='P&L (Vertical)'!D18/'BS (Ver & Horz)'!D21 -> 0.1971894 | H10: 2. Profitability ratio | J10: There is a slight increase in the net profit margin which shows they are managing their costs well leading to a higher profitability from total income. There is a 2% decrease in the gross profit margin due to the rising production costs or the company may have faced increased raw material costs or competitive pressure reducing margins. The return on assets declined a bit, implying that asset utilization efficiency dropped, possibly due to higher asset base or operational inefficiencies. There is a 17% rise in the return on equity which indicates the company generated significantly more profit for every unit of shareholder equity, this could be due to increased leverage . There is a 0.63% decline in the return on capital employed, possibly due to increased tax expenses or capital costs.
C11: Earning Power | D11: EBIT/Average Total Asset | E11: ='P&L (Vertical)'!C14/'BS (Ver & Horz)'!C21 -> 0.29778372 | F11: ='P&L (Vertical)'!D14/'BS (Ver & Horz)'!D21 -> 0.30701754
C12: Return on Equity | D12: EAT/ Total Equity | E12: ='P&L (Vertical)'!C18/'BS (Ver & Horz)'!C46 -> 0.95670996 | F12: ='P&L (Vertical)'!D18/'BS (Ver & Horz)'!D46 -> 0.78203763
C13: Return on Capital Employed | D13: EBIT-Tax/Average Total Asset | E13: =('P&L (Vertical)'!C14-'P&L (Vertical)'!C15)/'BS (Ver & Horz)'!C21 -> 0.20072304 | F13: =('P&L (Vertical)'!D14-'P&L (Vertical)'!D15)/'BS (Ver & Horz)'!D21 -> 0.20703545
B14: Turnover | C14: Asset Turnover Ratio | D14: Total Turnover/Average Total Asset | E14: ='P&L (Vertical)'!C7/'BS (Ver & Horz)'!C21 -> 1.3151525 | F14: ='P&L (Vertical)'!D7/'BS (Ver & Horz)'!D21 -> 1.3931257
C15: Fixed Asset Turnover | D15: Total Turnover/Average Fixed Asset | E15: ='P&L (Vertical)'!C7/'BS (Ver & Horz)'!C20 -> 2.0108147 | F15: ='P&L (Vertical)'!D7/'BS (Ver & Horz)'!D20 -> 2.0913733
C16: Working Capital Turnover | D16: Total Turnover/Working Capital | E16: ='P&L (Vertical)'!C7/('BS (Ver & Horz)'!C14-'BS (Ver & Horz)'!C29) -> 24.393586 | F16: ='P&L (Vertical)'!D7/('BS (Ver & Horz)'!D14-'BS (Ver & Horz)'!D29) -> 7782
C17: Receivable Turnover | D17: Total Turnover/Average Total Receivables | E17: ='P&L (Vertical)'!C7/'BS (Ver & Horz)'!C11 -> 9.9904478 | F17: ='P&L (Vertical)'!D7/'BS (Ver & Horz)'!D11 -> 9.6670807
C18: No. of days for receivables | D18: 360/Receivable Turnover | E18: =360/E17 -> 36.034421 | F18: =360/F17 -> 37.239784
B19: Capital Structure | C19: Debt-equity Ratio | D19: Debt/Equity | E19: ='BS (Ver & Horz)'!C33/'BS (Ver & Horz)'!C46 -> 4.0074774 | F19: ='BS (Ver & Horz)'!D33/'BS (Ver & Horz)'!D46 -> 2.9659212
C20: Long term Debt to Equity | D20: Long Term Debt/Equity | E20: =SUM('BS (Ver & Horz)'!C30:C32)/'BS (Ver & Horz)'!C46 -> 2.545061 | F20: =SUM('BS (Ver & Horz)'!D30:D32)/'BS (Ver & Horz)'!D46 -> 1.6425275
C21: Equity Multiplier | D21: Total Asset/Total Equity | E21: ='BS (Ver & Horz)'!C21/'BS (Ver & Horz)'!C46 -> 5.0074774 | F21: ='BS (Ver & Horz)'!D21/'BS (Ver & Horz)'!D46 -> 3.9659212
B22: Debt Coverage | C22: Interest Coverage Ratio | D22: EBIT/Interest | E22: ='P&L (Vertical)'!C14/'P&L (Vertical)'!C13 -> 72.865385 | F22: ='P&L (Vertical)'!D14/'P&L (Vertical)'!D13 -> 58.135593 | H22: 3. Turnover Ratio | J22: There is a bit decline in the total asset turnover due to decrease in the fixed assets turnover and this could be due to higher asset investments not yet translating into proportional revenue. There is a massive drop in the working capital turnover due to increased current asset . The recievables has increased which means receivables are converted into cash faster, indicating better credit management.
B23: Valuation | C23: Price to EPS Ratio | D23: Market price per share/EPS | E23: =92.39/'P&L (Vertical)'!C19 -> 18.552209 | F23: =92.39/'P&L (Vertical)'!D19 -> 20.761798
H28: 4.Capital structure | J28: The debt to equity ratio has increased by 1.04% and the long-Term debt to equity by 0.91% . This noticeable increase shows the company has taken on more debt relative to equity. While this can boost returns (as seen in ROE), it also raises financial risk due to higher interest obligations. The equity multiplier has also increased which reflects higher financial leverage, meaning the company relies more on debt financing, magnifying both potential returns and risks.
H35: 5. Debt coverage | J35: There is a 14% increase in the debt coverage ratio which indicates the company’s earnings are more than sufficient to cover interest payments, reducing the risk of financial distress despite higher debt levels.
H38: 6. Valuation | J38: A decrease implies the stock became cheaper relative to its earnings. This could result from either a drop in market price or improved earnings.

Sheet Cashflow Statement
A1: Exhibit 1.8 | C1: COLGATE-PALMOLIVE COMPANY | H1: Interpretation
C3: For the year ended December 31, | H3: For the operating activity
C4: (Dollars in Millions Except Per Share Amounts)
D5: 2011 | E5: 2010 | F5: 2009 | H5: Trend : | I5: The net cash provided by operating activities decreased over the three years, from $3,277 million in 2009 to $3,211 million in 2010 and further down to $2,896 million in 2011.
C6: Operating Activities
C7: Net income including noncontrolling interests | D7: 2554 | E7: 2313 | F7: 2397
C8: Adjustments to reconcile net income including noncontrolling interests to net cash provided by operations
C9: Depreciation and amortization | D9: 421 | E9: 376 | F9: 351 | H9: Analysis : | I9: Key components influencing this trend include depreciation and amortization, which increased over the years, while restructuring and termination benefits, as well as stock-based compensation, remained relatively stable. Variations in working capital components, such as changes in receivables, inventories, and accounts payable, also impacted operational cash flows.
C10: Restructuring and termination benefits, net of cash | D10: 103 | E10: 86 | F10: -18
C11: Venezuela hyperinflationary transition charge | E11: 271
C12: Gain before tax on sales of non-core product lines | D12: -207 | E12: -50 | F12: -5
C13: Voluntary benefit plan contributions | D13: -178 | E13: -35 | F13: -73
C14: Stock based compensation expenses | D14: 122 | E14: 121 | F14: 117
C15: Deferred income taxes | D15: 88 | E15: 29 | F15: -23 | H15: For the Investing activity
C16: Cash effects of changes in:
C17: Receivables | D17: -130 | E17: 40 | F17: 57 | H17: Trend : | I17: From 2009 to 2010, the net cash used decreased significantly showing Colgate reduced its investment outflows. From 2010 to 2011, there is a sharp rise in the cash outflows which is almost doubling and increased the investing activities.
C18: Inventories | D18: -130 | E18: -10 | F18: 44
C19: Accounts payableand other accruals | D19: 199 | E19: -65 | F19: 294
C20: Other non-current assets and liablities | D20: 54 | E20: 135 | F20: 136
C21: Net cash provided by operations | D21: =SUM(D7:D20) -> 2896 | E21: =SUM(E7:E20) -> 3211 | F21: =SUM(F7:F20) -> 3277
C22: Investing Activities
C23: Capital Expenditures | D23: -537 | E23: -550 | F23: -575
C24: Sale of property and non core product lines | D24: 263 | E24: 42 | F24: 17 | H24: Analysis : | I24: Capital expenditures remained relatively stable, indicating continued investment in assets. However, 2011 saw a significant cash outflow of $966 million for acquisitions, which was absent in previous years. This indicates a strategic expansion through acquisitions, which could have long-term benefits but impacted short-term liquidity. Additionally, purchases and sales of marketable securities and investments show moderate fluctuations, highlighting financial portfolio adjustments.
C25: Purchase of marketable securities and investments | D25: -356 | E25: -308 | F25: -289
C26: Proceeds from sale of marketable securities and investments | D26: 423 | E26: 167
C27: Payment for acquisition, net of cash acquired | D27: -966
C28: Other non-current assets and liablities | D28: -40 | E28: -9 | F28: 6
C29: Net cash used in investing activities | D29: =SUM(D23:D28) -> -1213 | E29: =SUM(E23:E28) -> -658 | F29: =SUM(F23:F28) -> -841
C30: Financing Activities
C31: Principal payents on debt | D31: -4429 | E31: -4719 | F31: -3950 | H31: For the financing activity
C32: Proceeds from issuance of debt | D32: 5843 | E32: 5015 | F32: 3424
C33: Dividend Paid | D33: -1203 | E33: -1142 | F33: -981 | H33: Trend : | I33: There were substantial debt-related transactions, with proceeds from debt increasing significantly in 2011 to $5,843 million, compared to $5,015 million in 2010 and $3,424 million in 2009.
C34: Purchases of treasuary shares | D34: -1806 | E34: -2020 | F34: -1063
C35: Proceeds from exercise of stock options and excees tax benefits | D35: 353 | E35: 242 | F35: 300
C36: Net cash used in financing activities | D36: =SUM(D31:D35) -> -1242 | E36: =SUM(E31:E35) -> -2624 | F36: =SUM(F30:F35) -> -2270
C37: Effect of exchange rate change on cash and cash equivalents | D37: -53 | E37: -39 | F37: -121
C38: Net increase (decrease) in cash and cash equivalence | D38: =D21+D29+D36+D37 -> 388 | E38: =E21+E29+E36+E37 -> -110 | F38: =F21+F29+F36+F37 -> 45 | H38: Analysis : | I38: Financing activities reveal the company’s capital structure management. This suggests reliance on external borrowing, possibly to fund acquisitions or other strategic initiatives. Principal payments on debt were also high, showing active debt management. Dividend payments increased steadily, reflecting the company’s commitment to shareholder returns. The repurchase of treasury shares remained significant, particularly in 2010 and 2011, indicating efforts to enhance shareholder value.
C39: Cash and cash equivalents at beginning of the yaer | D39: 490 | E39: 600 | F39: 555
C40: Cash and cash equivalents at end of the yaer | D40: =SUM(D38:D39) -> 878 | E40: =SUM(E38:E39) -> 490 | F40: =SUM(F38:F39) -> 600
C41: Supplemental cash flow information
...
