Workbook
Name IQ_CH: 110000
Name IQ_CQ: 5000
Name IQ_CY: 10000
Name IQ_DAILY: 500000
Name IQ_FH: 100000
Name IQ_FQ: 500
Name IQ_FY: 1000
Name IQ_LTM: 2000
Name IQ_MONTH: 15000
Name IQ_NTM: 6000
Name IQ_WEEK: 50000
Name IQ_YTD: 3000
Name UPDATE: '[1]Data Sheet'!$E$1
Name UPDATE: 'Data Sheet'!$E$1

Sheet Historical FS
B2: ="Historical Financial Statements- "&'Data Sheet'!B1 -> Historical Financial Statements- HINDUSTAN AERONAUTICS LTD
B3: Years | C3: =IFERROR('Data Sheet'!B16,0) -> 42460 | D3: =IFERROR('Data Sheet'!C16,0) -> 42825 | E3: =IFERROR('Data Sheet'!D16,0) -> 43190 | F3: =IFERROR('Data Sheet'!E16,0) -> 43555 | G3: =IFERROR('Data Sheet'!F16,0) -> 43921 | H3: =IFERROR('Data Sheet'!G16,0) -> 44286 | I3: =IFERROR('Data Sheet'!H16,0) -> 44651 | J3: =IFERROR('Data Sheet'!I16,0) -> 45016 | ... L3: =IFERROR('Data Sheet'!K16,0) -> 45747 | M3: LTM
A5: # | B5: Income Statement
B6: ='Data Sheet'!A17 -> Sales | C6: =IFERROR('Data Sheet'!B17,0) -> 16758.5 | D6: =IFERROR('Data Sheet'!C17,0) -> 17949.92 | E6: =IFERROR('Data Sheet'!D17,0) -> 18519.74 | F6: =IFERROR('Data Sheet'!E17,0) -> 20008 | G6: =IFERROR('Data Sheet'!F17,0) -> 21445.16 | H6: =IFERROR('Data Sheet'!G17,0) -> 22882.32 | I6: =IFERROR('Data Sheet'!H17,0) -> 24620.02 | J6: =IFERROR('Data Sheet'!I17,0) -> 26927.46 | ... L6: =IFERROR('Data Sheet'!K17,0) -> 30980.95 | M6: =IFERROR(SUM('Data Sheet'!H42:K42),0) -> 32104.78
B7: Sales Growth | C7: - | D7: =D6/C6-1 -> 0.071093475 | E7: =E6/D6-1 -> 0.031744988 | F7: =F6/E6-1 -> 0.080360739 | G7: =G6/F6-1 -> 0.071829268 | H7: =H6/G6-1 -> 0.067015588 | I7: =I6/H6-1 -> 0.075940726 | J7: =J6/I6-1 -> 0.093722101 | K7: =K6/J6-1 -> 0.12825643 | ... M7: =M6/L6-1 -> 0.036274872
B9: COGS | C9: =IFERROR(SUM('Data Sheet'!B18,'Data Sheet'!B20,'Data Sheet'!B21,'Data Sheet'!B22)-1*'Data Sheet'!B19,0) -> 12512.9 | D9: =IFERROR(SUM('Data Sheet'!C18,'Data Sheet'!C20,'Data Sheet'!C21,'Data Sheet'!C22)-1*'Data Sheet'!C19,0) -> 13838.91 | E9: =IFERROR(SUM('Data Sheet'!D18,'Data Sheet'!D20,'Data Sheet'!D21,'Data Sheet'!D22)-1*'Data Sheet'!D19,0) -> 14219.92 | F9: =IFERROR(SUM('Data Sheet'!E18,'Data Sheet'!E20,'Data Sheet'!E21,'Data Sheet'!E22)-1*'Data Sheet'!E19,0) -> 14087.52 | G9: =IFERROR(SUM('Data Sheet'!F18,'Data Sheet'!F20,'Data Sheet'!F21,'Data Sheet'!F22)-1*'Data Sheet'!F19,0) -> 14937.2 | H9: =IFERROR(SUM('Data Sheet'!G18,'Data Sheet'!G20,'Data Sheet'!G21,'Data Sheet'!G22)-1*'Data Sheet'!G19,0) -> 16337.81 | I9: =IFERROR(SUM('Data Sheet'!H18,'Data Sheet'!H20,'Data Sheet'!H21,'Data Sheet'!H22)-1*'Data Sheet'!H19,0) -> 15494.02 | J9: =IFERROR(SUM('Data Sheet'!I18,'Data Sheet'!I20,'Data Sheet'!I21,'Data Sheet'!I22)-1*'Data Sheet'!I19,0) -> 16160.85 | ... L9: =IFERROR(SUM('Data Sheet'!K18,'Data Sheet'!K20,'Data Sheet'!K21,'Data Sheet'!K22)-1*'Data Sheet'!K19,0) -> 19124.16 | M9: =IFERROR(SUM('Data Sheet'!H43:K43),0) -> 22287.08
B10: COGS % of Sales | C10: =IFERROR(C9/C6,0) -> 0.7466599 | D10: =IFERROR(D9/D6,0) -> 0.77097335 | E10: =IFERROR(E9/E6,0) -> 0.76782503 | F10: =IFERROR(F9/F6,0) -> 0.70409436 | G10: =IFERROR(G9/G6,0) -> 0.69653013 | H10: =IFERROR(H9/H6,0) -> 0.71399272 | I10: =IFERROR(I9/I6,0) -> 0.62932605 | J10: =IFERROR(J9/J6,0) -> 0.60016244 | ... M10: =IFERROR(M9/M6,0) -> 0.69419818
B12: Gross Profit | C12: =C6-C9 -> 4245.6 | D12: =D6-D9 -> 4111.01 | E12: =E6-E9 -> 4299.82 | F12: =F6-F9 -> 5920.48 | G12: =G6-G9 -> 6507.96 | H12: =H6-H9 -> 6544.51 | I12: =I6-I9 -> 9126 | J12: =J6-J9 -> 10766.61 | ... M12: =M6-M9 -> 9817.7
B13: Gross Profit % of sales | C13: =IFERROR(C12/C6,0) -> 0.2533401 | D13: =IFERROR(D12/D6,0) -> 0.22902665 | E13: =IFERROR(E12/E6,0) -> 0.23217497 | F13: =IFERROR(F12/F6,0) -> 0.29590564 | G13: =IFERROR(G12/G6,0) -> 0.30346987 | H13: =IFERROR(H12/H6,0) -> 0.28600728 | I13: =IFERROR(I12/I6,0) -> 0.37067395 | J13: =IFERROR(J12/J6,0) -> 0.39983756 | ... M13: =IFERROR(M12/M6,0) -> 0.30580182
B15: Selling & General Expenses | C15: =IFERROR(SUM('Data Sheet'!B23:B24),0) -> 1771.7 | D15: =IFERROR(SUM('Data Sheet'!C23:C24),0) -> 880.32 | E15: =IFERROR(SUM('Data Sheet'!D23:D24),0) -> 851.13 | F15: =IFERROR(SUM('Data Sheet'!E23:E24),0) -> 1369.45 | G15: =IFERROR(SUM('Data Sheet'!F23:F24),0) -> 1593.72 | H15: =IFERROR(SUM('Data Sheet'!G23:G24),0) -> 1200.53 | I15: =IFERROR(SUM('Data Sheet'!H23:H24),0) -> 3710.63 | J15: =IFERROR(SUM('Data Sheet'!I23:I24),0) -> 4080.95 | ... L15: =IFERROR(SUM('Data Sheet'!K23:K24),0) -> 2235.77 | M15: =M18-M12 -> 1424.29
B16: S&G % of sales | C16: =IFERROR(C15/C6,0) -> 0.10571949 | D16: =IFERROR(D15/D6,0) -> 0.049043116 | E16: =IFERROR(E15/E6,0) -> 0.045957989 | F16: =IFERROR(F15/F6,0) -> 0.068445122 | G16: =IFERROR(G15/G6,0) -> 0.074316069 | H16: =IFERROR(H15/H6,0) -> 0.052465397 | I16: =IFERROR(I15/I6,0) -> 0.15071596 | J16: =IFERROR(J15/J6,0) -> 0.15155347 | ... M16: =IFERROR(M15/M6,0) -> 0.044363799
B18: EBITDA | C18: =C12-C15 -> 2473.9 | D18: =D12-D15 -> 3230.69 | E18: =E12-E15 -> 3448.69 | F18: =F12-F15 -> 4551.03 | G18: =G12-G15 -> 4914.24 | H18: =H12-H15 -> 5343.98 | I18: =I12-I15 -> 5415.37 | J18: =J12-J15 -> 6685.66 | ... L18: =L12-L15 -> 9621.02 | M18: =SUM('Data Sheet'!H50:K50)+SUM('Data Sheet'!H45:K45) -> 11241.99
B19: EBITDA % of Sales | C19: =IFERROR(C18/C6,0) -> 0.14762061 | D19: =IFERROR(D18/D6,0) -> 0.17998353 | E19: =IFERROR(E18/E6,0) -> 0.18621698 | F19: =IFERROR(F18/F6,0) -> 0.22746052 | G19: =IFERROR(G18/G6,0) -> 0.2291538 | H19: =IFERROR(H18/H6,0) -> 0.23354188 | I19: =IFERROR(I18/I6,0) -> 0.21995799 | J19: =IFERROR(J18/J6,0) -> 0.24828409 | ... M19: =IFERROR(M18/M6,0) -> 0.35016561
B21: Other Income | C21: =IFERROR('Data Sheet'!B25,0) -> 1608.1 | D21: =IFERROR('Data Sheet'!C25,0) -> 1058.2 | E21: =IFERROR('Data Sheet'!D25,0) -> 775.7 | F21: =IFERROR('Data Sheet'!E25,0) -> 376.26 | G21: =IFERROR('Data Sheet'!F25,0) -> 422.51 | H21: =IFERROR('Data Sheet'!G25,0) -> 364.28 | I21: =IFERROR('Data Sheet'!H25,0) -> 984.93 | J21: =IFERROR('Data Sheet'!I25,0) -> 1672.92 | ... L21: =IFERROR('Data Sheet'!K25,0) -> 2608.23 | M21: =IFERROR(SUM('Data Sheet'!I44:K44),0) -> 2321.07
B22: % of Sales | C22: =IFERROR(C21/C6,0) -> 0.095957275 | D22: =IFERROR(D21/D6,0) -> 0.058952909 | E22: =IFERROR(E21/E6,0) -> 0.041885037 | F22: =IFERROR(F21/F6,0) -> 0.018805478 | G22: =IFERROR(G21/G6,0) -> 0.019701881 | H22: =IFERROR(H21/H6,0) -> 0.015919714 | I22: =IFERROR(I21/I6,0) -> 0.040005248 | J22: =IFERROR(J21/J6,0) -> 0.062126914 | ... M22: =IFERROR(M21/M6,0) -> 0.072296711
B24: Interest | C24: =IFERROR('Data Sheet'!B27,0) -> 5.9 | D24: =IFERROR('Data Sheet'!C27,0) -> 16.45 | E24: =IFERROR('Data Sheet'!D27,0) -> 34.62 | F24: =IFERROR('Data Sheet'!E27,0) -> 177.6 | G24: =IFERROR('Data Sheet'!F27,0) -> 359.59 | H24: =IFERROR('Data Sheet'!G27,0) -> 266.89 | I24: =IFERROR('Data Sheet'!H27,0) -> 65.24 | J24: =IFERROR('Data Sheet'!I27,0) -> 64.41 | ... L24: =IFERROR('Data Sheet'!K27,0) -> 21.62 | M24: =IFERROR(SUM('Data Sheet'!H46:K46),0) -> 9.18
B25: Interest % of Sales | C25: =IFERROR(C24/C6,0) -> 0.00035206015 | D25: =IFERROR(D24/D6,0) -> 0.00091643862 | E25: =IFERROR(E24/E6,0) -> 0.0018693567 | F25: =IFERROR(F24/F6,0) -> 0.0088764494 | G25: =IFERROR(G24/G6,0) -> 0.016767886 | H25: =IFERROR(H24/H6,0) -> 0.01166359 | I25: =IFERROR(I24/I6,0) -> 0.002649876 | J25: =IFERROR(J24/J6,0) -> 0.002391982 | ... M25: =IFERROR(M24/M6,0) -> 0.00028593873
B27: Depreciation | C27: =IFERROR('Data Sheet'!B26,0) -> 862.8 | D27: =IFERROR('Data Sheet'!C26,0) -> 680.68 | E27: =IFERROR('Data Sheet'!D26,0) -> 947.09 | F27: =IFERROR('Data Sheet'!E26,0) -> 1025.26 | G27: =IFERROR('Data Sheet'!F26,0) -> 998.52 | H27: =IFERROR('Data Sheet'!G26,0) -> 1157.89 | I27: =IFERROR('Data Sheet'!H26,0) -> 1110.53 | J27: =IFERROR('Data Sheet'!I26,0) -> 1784.67 | ... L27: =IFERROR('Data Sheet'!K26,0) -> 1340.37 | M27: =IFERROR(SUM('Data Sheet'!H45:K45),0) -> 1424.29
B28: Depreciation % of Sales | C28: =IFERROR(C27/C6,0) -> 0.051484321 | D28: =IFERROR(D27/D6,0) -> 0.03792106 | E28: =IFERROR(E27/E6,0) -> 0.051139487 | F28: =IFERROR(F27/F6,0) -> 0.051242503 | G28: =IFERROR(G27/G6,0) -> 0.046561555 | H28: =IFERROR(H27/H6,0) -> 0.050601949 | I28: =IFERROR(I27/I6,0) -> 0.045106787 | J28: =IFERROR(J27/J6,0) -> 0.066276953 | ... M28: =IFERROR(M27/M6,0) -> 0.044363799
B30: Profit Before Tax | C30: =IFERROR(SUM(C18,C21)-(SUM(C24,C27)),0) -> 3213.3 | D30: =IFERROR(SUM(D18,D21)-(SUM(D24,D27)),0) -> 3591.76 | E30: =IFERROR(SUM(E18,E21)-(SUM(E24,E27)),0) -> 3242.68 | F30: =IFERROR(SUM(F18,F21)-(SUM(F24,F27)),0) -> 3724.43 | G30: =IFERROR(SUM(G18,G21)-(SUM(G24,G27)),0) -> 3978.64 | H30: =IFERROR(SUM(H18,H21)-(SUM(H24,H27)),0) -> 4283.48 | I30: =IFERROR(SUM(I18,I21)-(SUM(I24,I27)),0) -> 5224.53 | J30: =IFERROR(SUM(J18,J21)-(SUM(J24,J27)),0) -> 6509.5 | ... M30: =IFERROR(SUM(M18,M21)-(SUM(M24,M27)),0) -> 12129.59
B31: PBT % of sales | C31: =IFERROR(C30/C6,0) -> 0.1917415 | D31: =IFERROR(D30/D6,0) -> 0.20009894 | E31: =IFERROR(E30/E6,0) -> 0.17509317 | F31: =IFERROR(F30/F6,0) -> 0.18614704 | G31: =IFERROR(G30/G6,0) -> 0.18552624 | H31: =IFERROR(H30/H6,0) -> 0.18719605 | I31: =IFERROR(I30/I6,0) -> 0.21220657 | J31: =IFERROR(J30/J6,0) -> 0.24174207 | ... M31: =IFERROR(M30/M6,0) -> 0.37781259
B33: Tax | C33: =IFERROR('Data Sheet'!B29,0) -> 1209 | D33: =IFERROR('Data Sheet'!C29,0) -> 966.95 | E33: =IFERROR('Data Sheet'!D29,0) -> 1252.43 | F33: =IFERROR('Data Sheet'!E29,0) -> 1396.28 | G33: =IFERROR('Data Sheet'!F29,0) -> 1095.99 | H33: =IFERROR('Data Sheet'!G29,0) -> 1037.93 | I33: =IFERROR('Data Sheet'!H29,0) -> 144.65 | J33: =IFERROR('Data Sheet'!I29,0) -> 681.77 | ... L33: =IFERROR('Data Sheet'!K29,0) -> 2503.21 | M33: =IFERROR(SUM('Data Sheet'!H48:K48),0) -> 2872.89
B34: Effective Tax Rate | C34: =IFERROR(C33/C30,0) -> 0.37624872 | D34: =IFERROR(D33/D30,0) -> 0.26921342 | E34: =IFERROR(E33/E30,0) -> 0.38623299 | F34: =IFERROR(F33/F30,0) -> 0.37489764 | G34: =IFERROR(G33/G30,0) -> 0.2754685 | H34: =IFERROR(H33/H30,0) -> 0.24230999 | I34: =IFERROR(I33/I30,0) -> 0.027686701 | J34: =IFERROR(J33/J30,0) -> 0.10473462 | ... M34: =IFERROR(M33/M30,0) -> 0.23684972
B36: Net Profit | C36: =C30-C33 -> 2004.3 | D36: =D30-D33 -> 2624.81 | E36: =E30-E33 -> 1990.25 | F36: =F30-F33 -> 2328.15 | G36: =G30-G33 -> 2882.65 | H36: =H30-H33 -> 3245.55 | I36: =I30-I33 -> 5079.88 | J36: =J30-J33 -> 5827.73 | ... M36: =M30-M33 -> 9256.7
B37: Net Margins | C37: =IFERROR(C36/C6,0) -> 0.11959901 | D37: =IFERROR(D36/D6,0) -> 0.14622962 | E37: =IFERROR(E36/E6,0) -> 0.10746641 | F37: =IFERROR(F36/F6,0) -> 0.11636096 | G37: =IFERROR(G36/G6,0) -> 0.13441961 | H37: =IFERROR(H36/H6,0) -> 0.14183658 | I37: =IFERROR(I36/I6,0) -> 0.20633127 | J37: =IFERROR(J36/J6,0) -> 0.21642331 | ... M37: =IFERROR(M36/M6,0) -> 0.28832778
B39: No. of Equity Shares | C39: =IFERROR('Data Sheet'!B93,0) -> 72.3 | D39: =IFERROR('Data Sheet'!C93,0) -> 72.3 | E39: =IFERROR('Data Sheet'!D93,0) -> 66.88 | F39: =IFERROR('Data Sheet'!E93,0) -> 66.88 | G39: =IFERROR('Data Sheet'!F93,0) -> 66.88 | H39: =IFERROR('Data Sheet'!G93,0) -> 66.88 | I39: =IFERROR('Data Sheet'!H93,0) -> 66.88 | J39: =IFERROR('Data Sheet'!I93,0) -> 66.88 | ... M39: =IFERROR('Data Sheet'!L93,0) -> 0
B41: Earnings Per Share | C41: =IFERROR(C36/C39,0) -> 27.721992 | D41: =IFERROR(D36/D39,0) -> 36.304426 | E41: =IFERROR(E36/E39,0) -> 29.758523 | F41: =IFERROR(F36/F39,0) -> 34.810855 | G41: =IFERROR(G36/G39,0) -> 43.101824 | H41: =IFERROR(H36/H39,0) -> 48.527961 | I41: =IFERROR(I36/I39,0) -> 75.955144 | J41: =IFERROR(J36/J39,0) -> 87.137111 | ... M41: =IFERROR(M36/M39,0) -> 0
B42: EPS growth | C42: - | D42: =IFERROR(D41/C41-1,0) -> 0.30958938 | E42: =IFERROR(E41/D41-1,0) -> -0.18030593 | F42: =IFERROR(F41/E41-1,0) -> 0.16977767 | G42: =IFERROR(G41/F41-1,0) -> 0.23817194 | H42: =IFERROR(H41/G41-1,0) -> 0.12589111 | I42: =IFERROR(I41/H41-1,0) -> 0.5651831 | J42: =IFERROR(J41/I41-1,0) -> 0.14721804 | K42: =IFERROR(K41/J41-1,0) -> 0.30770472 | ... M42: =IFERROR(M41/L41-1,0) -> -1
B44: Dividend Per Share | C44: =IFERROR('Data Sheet'!B31/'Historical FS'!C39,0) -> 8.7 | D44: =IFERROR('Data Sheet'!C31/'Historical FS'!D39,0) -> 11.065007 | E44: =IFERROR('Data Sheet'!D31/'Historical FS'!E39,0) -> 16.08448 | F44: =IFERROR('Data Sheet'!E31/'Historical FS'!F39,0) -> 9.8996711 | G44: =IFERROR('Data Sheet'!F31/'Historical FS'!G39,0) -> 16.624551 | H44: =IFERROR('Data Sheet'!G31/'Historical FS'!H39,0) -> 14.999551 | I44: =IFERROR('Data Sheet'!H31/'Historical FS'!I39,0) -> 19.999402 | J44: =IFERROR('Data Sheet'!I31/'Historical FS'!J39,0) -> 27.499103 | ... M44: =IFERROR('Data Sheet'!L31/'Historical FS'!M39,0) -> 0
B45: DPS Growth | C45: - | D45: =IFERROR(D44/C44-1,0) -> 0.27183988 | E45: =IFERROR(E44/D44-1,0) -> 0.45363485 | F45: =IFERROR(F44/E44-1,0) -> -0.38452028 | G45: =IFERROR(G44/F44-1,0) -> 0.67930342 | H45: =IFERROR(H44/G44-1,0) -> -0.097746998 | I45: =IFERROR(I44/H44-1,0) -> 0.33333333 | J45: =IFERROR(J44/I44-1,0) -> 0.37499626 | K45: =IFERROR(K44/J44-1,0) -> 0.27273073 | ... M45: =IFERROR(M44/L44-1,0) -> -1
B46: Dividend Payout Ratio | C46: =IFERROR(C44/C41,0) -> 0.31383026 | D46: =IFERROR(D44/D41,0) -> 0.30478397 | E46: =IFERROR(E44/E41,0) -> 0.54049994 | F46: =IFERROR(F44/F41,0) -> 0.2843846 | G46: =IFERROR(G44/G41,0) -> 0.38570413 | H46: =IFERROR(H44/H41,0) -> 0.30909091 | I46: =IFERROR(I44/I41,0) -> 0.26330543 | J46: =IFERROR(J44/J41,0) -> 0.31558428 | ... M46: =IFERROR(M44/M41,0) -> 0
B47: Retained Earnings | C47: =IFERROR(1-C46,0) -> 0.68616974 | D47: =IFERROR(1-D46,0) -> 0.69521603 | E47: =IFERROR(1-E46,0) -> 0.45950006 | F47: =IFERROR(1-F46,0) -> 0.7156154 | G47: =IFERROR(1-G46,0) -> 0.61429587 | H47: =IFERROR(1-H46,0) -> 0.69090909 | I47: =IFERROR(1-I46,0) -> 0.73669457 | J47: =IFERROR(1-J46,0) -> 0.68441572 | ... M47: =IFERROR(1-M46,0) -> 1
A50: # | B50: Balance Sheet
B51: Equity Share Capital | C51: =IFERROR('Data Sheet'!B57,0) -> 361.5 | D51: =IFERROR('Data Sheet'!C57,0) -> 361.5 | E51: =IFERROR('Data Sheet'!D57,0) -> 334.39 | F51: =IFERROR('Data Sheet'!E57,0) -> 334.39 | G51: =IFERROR('Data Sheet'!F57,0) -> 334.39 | H51: =IFERROR('Data Sheet'!G57,0) -> 334.39 | I51: =IFERROR('Data Sheet'!H57,0) -> 334.39 | J51: =IFERROR('Data Sheet'!I57,0) -> 334.39 | ... L51: =IFERROR('Data Sheet'!K57,0) -> 334.39
B52: Reserves | C52: =IFERROR('Data Sheet'!B58,0) -> 10670.9 | D52: =IFERROR('Data Sheet'!C58,0) -> 12197.61 | E52: =IFERROR('Data Sheet'!D58,0) -> 9176.86 | F52: =IFERROR('Data Sheet'!E58,0) -> 11747.73 | G52: =IFERROR('Data Sheet'!F58,0) -> 12914.12 | H52: =IFERROR('Data Sheet'!G58,0) -> 15089.51 | I52: =IFERROR('Data Sheet'!H58,0) -> 18978.74 | J52: =IFERROR('Data Sheet'!I58,0) -> 23237.76 | ... L52: =IFERROR('Data Sheet'!K58,0) -> 34647.22
B53: Borrowings | C53: =IFERROR('Data Sheet'!B59,0) -> 79.8 | D53: =IFERROR('Data Sheet'!C59,0) -> 1022.03 | E53: =IFERROR('Data Sheet'!D59,0) -> 904.52 | F53: =IFERROR('Data Sheet'!E59,0) -> 4116.2 | G53: =IFERROR('Data Sheet'!F59,0) -> 5926.97 | H53: =IFERROR('Data Sheet'!G59,0) -> 53.28 | I53: =IFERROR('Data Sheet'!H59,0) -> 49.27 | J53: =IFERROR('Data Sheet'!I59,0) -> 51.69 | ... L53: =IFERROR('Data Sheet'!K59,0) -> 51.44
B54: Other Liabilities | C54: =IFERROR('Data Sheet'!B60,0) -> 45419.7 | D54: =IFERROR('Data Sheet'!C60,0) -> 38162.56 | E54: =IFERROR('Data Sheet'!D60,0) -> 38046.84 | F54: =IFERROR('Data Sheet'!E60,0) -> 35298.01 | G54: =IFERROR('Data Sheet'!F60,0) -> 35027.18 | H54: =IFERROR('Data Sheet'!G60,0) -> 37619.24 | I54: =IFERROR('Data Sheet'!H60,0) -> 40891.94 | J54: =IFERROR('Data Sheet'!I60,0) -> 45652.16 | ... L54: =IFERROR('Data Sheet'!K60,0) -> 73665.41
B55: Total Liabilities | C55: =IFERROR(SUM(C51:C54),0) -> 56531.9 | D55: =IFERROR(SUM(D51:D54),0) -> 51743.7 | E55: =IFERROR(SUM(E51:E54),0) -> 48462.61 | F55: =IFERROR(SUM(F51:F54),0) -> 51496.33 | G55: =IFERROR(SUM(G51:G54),0) -> 54202.66 | H55: =IFERROR(SUM(H51:H54),0) -> 53096.42 | I55: =IFERROR(SUM(I51:I54),0) -> 60254.34 | J55: =IFERROR(SUM(J51:J54),0) -> 69276 | ... L55: =IFERROR(SUM(L51:L54),0) -> 108698.46
B57: Non Current Assets Net Block | C57: =IFERROR('Data Sheet'!B62,0) -> 6925.2 | D57: =IFERROR('Data Sheet'!C62,0) -> 7349.56 | E57: =IFERROR('Data Sheet'!D62,0) -> 7566.22 | F57: =IFERROR('Data Sheet'!E62,0) -> 7459.35 | G57: =IFERROR('Data Sheet'!F62,0) -> 7357.49 | H57: =IFERROR('Data Sheet'!G62,0) -> 7165.88 | I57: =IFERROR('Data Sheet'!H62,0) -> 6765.88 | J57: =IFERROR('Data Sheet'!I62,0) -> 6834.4 | ... L57: =IFERROR('Data Sheet'!K62,0) -> 6670.8
B58: Capital Work in Progress | C58: =IFERROR('Data Sheet'!B63,0) -> 1025.4 | D58: =IFERROR('Data Sheet'!C63,0) -> 1389.4 | E58: =IFERROR('Data Sheet'!D63,0) -> 1461.72 | F58: =IFERROR('Data Sheet'!E63,0) -> 1502.11 | G58: =IFERROR('Data Sheet'!F63,0) -> 2042.69 | H58: =IFERROR('Data Sheet'!G63,0) -> 1949.6 | I58: =IFERROR('Data Sheet'!H63,0) -> 2472.94 | J58: =IFERROR('Data Sheet'!I63,0) -> 1885 | ... L58: =IFERROR('Data Sheet'!K63,0) -> 3097.75
...

Sheet Financial Ratios
B2: ="Ratio Analysis- "&'Data Sheet'!B1 -> Ratio Analysis- HINDUSTAN AERONAUTICS LTD
B3: Years | C3: =IFERROR('Data Sheet'!B16,0) -> 42460 | D3: =IFERROR('Data Sheet'!C16,0) -> 42825 | E3: =IFERROR('Data Sheet'!D16,0) -> 43190 | F3: =IFERROR('Data Sheet'!E16,0) -> 43555 | G3: =IFERROR('Data Sheet'!F16,0) -> 43921 | H3: =IFERROR('Data Sheet'!G16,0) -> 44286 | I3: =IFERROR('Data Sheet'!H16,0) -> 44651 | J3: =IFERROR('Data Sheet'!I16,0) -> 45016 | ... L3: =IFERROR('Data Sheet'!K16,0) -> 45747 | M3: ='Historical FS'!M3 -> LTM | N3: Trend | O3: Mean | P3: Median
B5: Sales Growth | C5: =IFERROR('Historical FS'!C6/0-1,0) -> 0 | D5: =IFERROR('Historical FS'!D7,0) -> 0.071093475 | E5: =IFERROR('Historical FS'!E7,0) -> 0.031744988 | F5: =IFERROR('Historical FS'!F7,0) -> 0.080360739 | G5: =IFERROR('Historical FS'!G7,0) -> 0.071829268 | H5: =IFERROR('Historical FS'!H7,0) -> 0.067015588 | I5: =IFERROR('Historical FS'!I7,0) -> 0.075940726 | J5: =IFERROR('Historical FS'!J7,0) -> 0.093722101 | K5: =IFERROR('Historical FS'!K7,0) -> 0.12825643 | ... M5: =IFERROR('Historical FS'!M7,0) -> 0.036274872 | O5: =IFERROR(AVERAGE(D5:M5),0) -> 0.067598305 | P5: =IFERROR(MEDIAN(C5:M5),0) -> 0.071093475
B6: EBITDA | C6: =IFERROR('Historical FS'!C7/0-1,0) -> 0 | D6: =IFERROR('Historical FS'!D18/'Historical FS'!C18-1,0) -> 0.3059097 | E6: =IFERROR('Historical FS'!E18/'Historical FS'!D18-1,0) -> 0.067477845 | F6: =IFERROR('Historical FS'!F18/'Historical FS'!E18-1,0) -> 0.31964021 | G6: =IFERROR('Historical FS'!G18/'Historical FS'!F18-1,0) -> 0.079808307 | H6: =IFERROR('Historical FS'!H18/'Historical FS'!G18-1,0) -> 0.087447906 | I6: =IFERROR('Historical FS'!I18/'Historical FS'!H18-1,0) -> 0.013358957 | J6: =IFERROR('Historical FS'!J18/'Historical FS'!I18-1,0) -> 0.23457123 | K6: =IFERROR('Historical FS'!K18/'Historical FS'!J18-1,0) -> 0.4585815 | ... M6: =IFERROR('Historical FS'!M18/'Historical FS'!L18-1,0) -> 0.16848214 | O6: =IFERROR(AVERAGE(D6:M6),0) -> 0.17218892 | P6: =IFERROR(MEDIAN(C6:M6),0) -> 0.087447906
B7: PBT Growth | C7: =IFERROR('Historical FS'!C8/0-1,0) -> 0 | D7: =IFERROR('Historical FS'!D30/'Historical FS'!C30-1,0) -> 0.11777923 | E7: =IFERROR('Historical FS'!E30/'Historical FS'!D30-1,0) -> -0.097189122 | F7: =IFERROR('Historical FS'!F30/'Historical FS'!E30-1,0) -> 0.14856538 | G7: =IFERROR('Historical FS'!G30/'Historical FS'!F30-1,0) -> 0.06825474 | H7: =IFERROR('Historical FS'!H30/'Historical FS'!G30-1,0) -> 0.076619146 | I7: =IFERROR('Historical FS'!I30/'Historical FS'!H30-1,0) -> 0.21969287 | J7: =IFERROR('Historical FS'!J30/'Historical FS'!I30-1,0) -> 0.2459494 | K7: =IFERROR('Historical FS'!K30/'Historical FS'!J30-1,0) -> 0.57076273 | ... M7: =IFERROR('Historical FS'!M30/'Historical FS'!L30-1,0) -> 0.11615899 | O7: =IFERROR(AVERAGE(D7:M7),0) -> 0.15294186 | P7: =IFERROR(MEDIAN(C7:M7),0) -> 0.11615899
B8: Net Profit Growth | C8: =IFERROR('Historical FS'!C9/0-1,0) -> 0 | D8: =IFERROR('Historical FS'!D36/'Historical FS'!C36-1,0) -> 0.30958938 | E8: =IFERROR('Historical FS'!E36/'Historical FS'!D36-1,0) -> -0.24175464 | F8: =IFERROR('Historical FS'!F36/'Historical FS'!E36-1,0) -> 0.16977767 | G8: =IFERROR('Historical FS'!G36/'Historical FS'!F36-1,0) -> 0.23817194 | H8: =IFERROR('Historical FS'!H36/'Historical FS'!G36-1,0) -> 0.12589111 | I8: =IFERROR('Historical FS'!I36/'Historical FS'!H36-1,0) -> 0.5651831 | J8: =IFERROR('Historical FS'!J36/'Historical FS'!I36-1,0) -> 0.14721804 | K8: =IFERROR('Historical FS'!K36/'Historical FS'!J36-1,0) -> 0.30770472 | ... M8: =IFERROR('Historical FS'!M36/'Historical FS'!L36-1,0) -> 0.10672461 | O8: =IFERROR(AVERAGE(D8:M8),0) -> 0.18260135 | P8: =IFERROR(MEDIAN(C8:M8),0) -> 0.14721804
B9: Dividend Growth | C9: =IFERROR('Historical FS'!C10/0-1,0) -> 0 | D9: =IFERROR('Historical FS'!D44/'Historical FS'!C44-1,0) -> 0.27183988 | E9: =IFERROR('Historical FS'!E44/'Historical FS'!D44-1,0) -> 0.45363485 | F9: =IFERROR('Historical FS'!F44/'Historical FS'!E44-1,0) -> -0.38452028 | G9: =IFERROR('Historical FS'!G44/'Historical FS'!F44-1,0) -> 0.67930342 | H9: =IFERROR('Historical FS'!H44/'Historical FS'!G44-1,0) -> -0.097746998 | I9: =IFERROR('Historical FS'!I44/'Historical FS'!H44-1,0) -> 0.33333333 | J9: =IFERROR('Historical FS'!J44/'Historical FS'!I44-1,0) -> 0.37499626 | K9: =IFERROR('Historical FS'!K44/'Historical FS'!J44-1,0) -> 0.27273073 | ... M9: =IFERROR('Historical FS'!M44/'Historical FS'!L44-1,0) -> -1 | O9: =IFERROR(AVERAGE(D9:M9),0) -> 0.10464283 | P9: =IFERROR(MEDIAN(C9:M9),0) -> 0.27183988
B11: Gross Margin | C11: ='Historical FS'!C13 -> 0.2533401 | D11: ='Historical FS'!D13 -> 0.22902665 | E11: ='Historical FS'!E13 -> 0.23217497 | F11: ='Historical FS'!F13 -> 0.29590564 | G11: ='Historical FS'!G13 -> 0.30346987 | H11: ='Historical FS'!H13 -> 0.28600728 | I11: ='Historical FS'!I13 -> 0.37067395 | J11: ='Historical FS'!J13 -> 0.39983756 | ... M11: ='Historical FS'!M13 -> 0.30580182 | O11: =IFERROR(AVERAGE(C11:M11),0) -> 0.31672223 | P11: =IFERROR(MEDIAN(C11:M11),0) -> 0.30346987
B12: EBITDA Margin | C12: ='Historical FS'!C19 -> 0.14762061 | D12: ='Historical FS'!D19 -> 0.17998353 | E12: ='Historical FS'!E19 -> 0.18621698 | F12: ='Historical FS'!F19 -> 0.22746052 | G12: ='Historical FS'!G19 -> 0.2291538 | H12: ='Historical FS'!H19 -> 0.23354188 | I12: ='Historical FS'!I19 -> 0.21995799 | J12: ='Historical FS'!J19 -> 0.24828409 | ... M12: ='Historical FS'!M19 -> 0.35016561 | O12: =IFERROR(AVERAGE(C12:M12),0) -> 0.24126425 | P12: =IFERROR(MEDIAN(C12:M12),0) -> 0.2291538
B13: PBIT Margin | C13: =IFERROR((('Historical FS'!C18-'Historical FS'!C27)/'Historical FS'!C6),0) -> 0.096136289 | D13: =IFERROR((('Historical FS'!D18-'Historical FS'!D27)/'Historical FS'!D6),0) -> 0.14206247 | E13: =IFERROR((('Historical FS'!E18-'Historical FS'!E27)/'Historical FS'!E6),0) -> 0.13507749 | F13: =IFERROR((('Historical FS'!F18-'Historical FS'!F27)/'Historical FS'!F6),0) -> 0.17621801 | G13: =IFERROR((('Historical FS'!G18-'Historical FS'!G27)/'Historical FS'!G6),0) -> 0.18259225 | H13: =IFERROR((('Historical FS'!H18-'Historical FS'!H27)/'Historical FS'!H6),0) -> 0.18293993 | I13: =IFERROR((('Historical FS'!I18-'Historical FS'!I27)/'Historical FS'!I6),0) -> 0.1748512 | J13: =IFERROR((('Historical FS'!J18-'Historical FS'!J27)/'Historical FS'!J6),0) -> 0.18200714 | ... M13: =IFERROR((('Historical FS'!M18-'Historical FS'!M27)/'Historical FS'!M6),0) -> 0.30580182 | O13: =IFERROR(AVERAGE(C13:M13),0) -> 0.19269334 | P13: =IFERROR(MEDIAN(C13:M13),0) -> 0.18200714
B14: PBT Margin | C14: ='Historical FS'!C31 -> 0.1917415 | D14: ='Historical FS'!D31 -> 0.20009894 | E14: ='Historical FS'!E31 -> 0.17509317 | F14: ='Historical FS'!F31 -> 0.18614704 | G14: ='Historical FS'!G31 -> 0.18552624 | H14: ='Historical FS'!H31 -> 0.18719605 | I14: ='Historical FS'!I31 -> 0.21220657 | J14: ='Historical FS'!J31 -> 0.24174207 | ... M14: ='Historical FS'!M31 -> 0.37781259 | O14: =IFERROR(AVERAGE(C14:M14),0) -> 0.24044461 | P14: =IFERROR(MEDIAN(C14:M14),0) -> 0.20009894
B15: Net Profit Margin | C15: ='Historical FS'!C37 -> 0.11959901 | D15: ='Historical FS'!D37 -> 0.14622962 | E15: ='Historical FS'!E37 -> 0.10746641 | F15: ='Historical FS'!F37 -> 0.11636096 | G15: ='Historical FS'!G37 -> 0.13441961 | H15: ='Historical FS'!H37 -> 0.14183658 | I15: ='Historical FS'!I37 -> 0.20633127 | J15: ='Historical FS'!J37 -> 0.21642331 | ... M15: ='Historical FS'!M37 -> 0.28832778 | O15: =IFERROR(AVERAGE(C15:M15),0) -> 0.18161943 | P15: =IFERROR(MEDIAN(C15:M15),0) -> 0.14622962
B17: Sales Expenses (% of Sales) | C17: ='Historical FS'!C16 -> 0.10571949 | D17: ='Historical FS'!D16 -> 0.049043116 | E17: ='Historical FS'!E16 -> 0.045957989 | F17: ='Historical FS'!F16 -> 0.068445122 | G17: ='Historical FS'!G16 -> 0.074316069 | H17: ='Historical FS'!H16 -> 0.052465397 | I17: ='Historical FS'!I16 -> 0.15071596 | J17: ='Historical FS'!J16 -> 0.15155347 | ... M17: ='Historical FS'!M16 -> 0.044363799 | O17: =IFERROR(AVERAGE(C17:M17),0) -> 0.083524126 | P17: =IFERROR(MEDIAN(C17:M17),0) -> 0.07216596
B18: Depreciation (% of Sales) | C18: ='Historical FS'!C28 -> 0.051484321 | D18: ='Historical FS'!D28 -> 0.03792106 | E18: ='Historical FS'!E28 -> 0.051139487 | F18: ='Historical FS'!F28 -> 0.051242503 | G18: ='Historical FS'!G28 -> 0.046561555 | H18: ='Historical FS'!H28 -> 0.050601949 | I18: ='Historical FS'!I28 -> 0.045106787 | J18: ='Historical FS'!J28 -> 0.066276953 | ... M18: ='Historical FS'!M28 -> 0.044363799 | O18: =IFERROR(AVERAGE(C18:M18),0) -> 0.048570914 | P18: =IFERROR(MEDIAN(C18:M18),0) -> 0.046561555
B19: Operating Income (% of Sales) | C19: =C13 -> 0.096136289 | D19: =D13 -> 0.14206247 | E19: =E13 -> 0.13507749 | F19: =F13 -> 0.17621801 | G19: =G13 -> 0.18259225 | H19: =H13 -> 0.18293993 | I19: =I13 -> 0.1748512 | J19: =J13 -> 0.18200714 | ... M19: =M13 -> 0.30580182 | O19: =IFERROR(AVERAGE(C19:M19),0) -> 0.19269334 | P19: =IFERROR(MEDIAN(C19:M19),0) -> 0.18200714
B21: Return on Capital Employed | C21: =IFERROR(('Historical FS'!C18-'Historical FS'!C27)/(SUM('Historical FS'!C51:C53)),0) -> 0.14498479 | D21: =IFERROR(('Historical FS'!D18-'Historical FS'!D27)/(SUM('Historical FS'!D51:D53)),0) -> 0.18776112 | E21: =IFERROR(('Historical FS'!E18-'Historical FS'!E27)/(SUM('Historical FS'!E51:E53)),0) -> 0.24017427 | F21: =IFERROR(('Historical FS'!F18-'Historical FS'!F27)/(SUM('Historical FS'!F51:F53)),0) -> 0.2176627 | G21: =IFERROR(('Historical FS'!G18-'Historical FS'!G27)/(SUM('Historical FS'!G51:G53)),0) -> 0.20420454 | H21: =IFERROR(('Historical FS'!H18-'Historical FS'!H27)/(SUM('Historical FS'!H51:H53)),0) -> 0.27046852 | I21: =IFERROR(('Historical FS'!I18-'Historical FS'!I27)/(SUM('Historical FS'!I51:I53)),0) -> 0.22232988 | J21: =IFERROR(('Historical FS'!J18-'Historical FS'!J27)/(SUM('Historical FS'!J51:J53)),0) -> 0.2074595 | ... M21: =IFERROR(('Historical FS'!M18-'Historical FS'!M27)/(SUM('Historical FS'!M51:M53)),0) -> 0 | O21: =IFERROR(AVERAGE(C21:M21),0) -> 0.2015722 | P21: =IFERROR(MEDIAN(C21:M21),0) -> 0.2176627
B22: Retained Earnings % | C22: ='Historical FS'!C47 -> 0.68616974 | D22: ='Historical FS'!D47 -> 0.69521603 | E22: ='Historical FS'!E47 -> 0.45950006 | F22: ='Historical FS'!F47 -> 0.7156154 | G22: ='Historical FS'!G47 -> 0.61429587 | H22: ='Historical FS'!H47 -> 0.69090909 | I22: ='Historical FS'!I47 -> 0.73669457 | J22: ='Historical FS'!J47 -> 0.68441572 | ... M22: ='Historical FS'!M47 -> 1 | O22: =IFERROR(AVERAGE(C22:M22),0) -> 0.69598517 | P22: =IFERROR(MEDIAN(C22:M22),0) -> 0.69090909
B23: Return on Equity % | C23: =IFERROR('Historical FS'!C36/SUM('Historical FS'!C51:C53),0) -> 0.18036932 | D23: =IFERROR('Historical FS'!D36/SUM('Historical FS'!D51:D53),0) -> 0.19326875 | E23: =IFERROR('Historical FS'!E36/SUM('Historical FS'!E51:E53),0) -> 0.19108045 | F23: =IFERROR('Historical FS'!F36/SUM('Historical FS'!F51:F53),0) -> 0.14372787 | G23: =IFERROR('Historical FS'!G36/SUM('Historical FS'!G51:G53),0) -> 0.15033 | H23: =IFERROR('Historical FS'!H36/SUM('Historical FS'!H51:H53),0) -> 0.20969905 | I23: =IFERROR('Historical FS'!I36/SUM('Historical FS'!I51:I53),0) -> 0.26235797 | J23: =IFERROR('Historical FS'!J36/SUM('Historical FS'!J51:J53),0) -> 0.24668851 | ... M23: =IFERROR('Historical FS'!M36/SUM('Historical FS'!M51:M53),0) -> 0 | O23: =IFERROR(AVERAGE(C23:M23),0) -> 0.18885141 | P23: =IFERROR(MEDIAN(C23:M23),0) -> 0.19326875
B24: Self Sustained Growth Rate | C24: =IFERROR(C22*C23,0) -> 0.12376397 | D24: =IFERROR(D22*D23,0) -> 0.13436354 | E24: =IFERROR(E22*E23,0) -> 0.087801478 | F24: =IFERROR(F22*F23,0) -> 0.10285388 | G24: =IFERROR(G22*G23,0) -> 0.092347102 | H24: =IFERROR(H22*H23,0) -> 0.14488298 | I24: =IFERROR(I22*I23,0) -> 0.19327769 | J24: =IFERROR(J22*J23,0) -> 0.1688375 | ... M24: =IFERROR(M22*M23,0) -> 0 | O24: =IFERROR(AVERAGE(C24:M24),0) -> 0.12649251 | P24: =IFERROR(MEDIAN(C24:M24),0) -> 0.13436354
B25: Interest Coverage Ratio | C25: =IFERROR(('Historical FS'!C18-'Historical FS'!C27)/'Historical FS'!C24,0) -> 273.0678 | D25: =IFERROR(('Historical FS'!D18-'Historical FS'!D27)/'Historical FS'!D24,0) -> 155.01581 | E25: =IFERROR(('Historical FS'!E18-'Historical FS'!E27)/'Historical FS'!E24,0) -> 72.25881 | F25: =IFERROR(('Historical FS'!F18-'Historical FS'!F27)/'Historical FS'!F24,0) -> 19.852309 | G25: =IFERROR(('Historical FS'!G18-'Historical FS'!G27)/'Historical FS'!G24,0) -> 10.889402 | H25: =IFERROR(('Historical FS'!H18-'Historical FS'!H27)/'Historical FS'!H24,0) -> 15.684702 | I25: =IFERROR(('Historical FS'!I18-'Historical FS'!I27)/'Historical FS'!I24,0) -> 65.984672 | J25: =IFERROR(('Historical FS'!J18-'Historical FS'!J27)/'Historical FS'!J24,0) -> 76.090514 | ... M25: =IFERROR(('Historical FS'!M18-'Historical FS'!M27)/'Historical FS'!M24,0) -> 1069.4662 | O25: =IFERROR(AVERAGE(C25:M25),0) -> 212.45994 | P25: =IFERROR(MEDIAN(C25:M25),0) -> 76.090514
B27: Debtor Turnover Ratio | C27: =IFERROR('Historical FS'!C6/'Historical FS'!C63,0) -> 3.4647191 | D27: =IFERROR('Historical FS'!D6/(('Historical FS'!D63+'Historical FS'!C63)/2),0) -> 3.963741 | E27: =IFERROR('Historical FS'!E6/(('Historical FS'!E63+'Historical FS'!D63)/2),0) -> 3.3759108 | F27: =IFERROR('Historical FS'!F6/(('Historical FS'!F63+'Historical FS'!E63)/2),0) -> 2.0831316 | G27: =IFERROR('Historical FS'!G6/(('Historical FS'!G63+'Historical FS'!F63)/2),0) -> 1.8102734 | H27: =IFERROR('Historical FS'!H6/(('Historical FS'!H63+'Historical FS'!G63)/2),0) -> 2.7075215 | I27: =IFERROR('Historical FS'!I6/(('Historical FS'!I63+'Historical FS'!H63)/2),0) -> 4.7761441 | J27: =IFERROR('Historical FS'!J6/(('Historical FS'!J63+'Historical FS'!I63)/2),0) -> 5.7532944 | K27: =IFERROR('Historical FS'!K6/(('Historical FS'!K63+'Historical FS'!J63)/2),0) -> 6.508351 | ... M27: =IFERROR('Historical FS'!M6/(('Historical FS'!M63+'Historical FS'!L63)/2),0) -> 13.815073 | O27: =IFERROR(AVERAGE(C27:M27),0) -> 4.9951054 | P27: =IFERROR(MEDIAN(C27:M27),0) -> 3.963741
B28: Creditor Turnover Ratio | C28: =IFERROR('Historical FS'!C6/'Historical FS'!C54,0) -> 0.36896985 | D28: =IFERROR('Historical FS'!D6/(('Historical FS'!D54+'Historical FS'!C54)/2),0) -> 0.42951507 | E28: =IFERROR('Historical FS'!E6/(('Historical FS'!E54+'Historical FS'!D54)/2),0) -> 0.48602246 | F28: =IFERROR('Historical FS'!F6/(('Historical FS'!F54+'Historical FS'!E54)/2),0) -> 0.54558705 | G28: =IFERROR('Historical FS'!G6/(('Historical FS'!G54+'Historical FS'!F54)/2),0) -> 0.60988559 | H28: =IFERROR('Historical FS'!H6/(('Historical FS'!H54+'Historical FS'!G54)/2),0) -> 0.62996415 | I28: =IFERROR('Historical FS'!I6/(('Historical FS'!I54+'Historical FS'!H54)/2),0) -> 0.62717233 | J28: =IFERROR('Historical FS'!J6/(('Historical FS'!J54+'Historical FS'!I54)/2),0) -> 0.62228297 | K28: =IFERROR('Historical FS'!K6/(('Historical FS'!K54+'Historical FS'!J54)/2),0) -> 0.6240035 | ... M28: =IFERROR('Historical FS'!M6/(('Historical FS'!M54+'Historical FS'!L54)/2),0) -> 0.87163786 | O28: =IFERROR(AVERAGE(C28:M28),0) -> 0.57356385 | P28: =IFERROR(MEDIAN(C28:M28),0) -> 0.60988559
B29: Inventory Turnover Ratio | C29: =IFERROR('Historical FS'!C6/'Historical FS'!C64,0) -> 0.69880367 | D29: =IFERROR('Historical FS'!D6/(('Historical FS'!D64+'Historical FS'!C64)/2),0) -> 0.78898268 | E29: =IFERROR('Historical FS'!E6/(('Historical FS'!E64+'Historical FS'!D64)/2),0) -> 0.88929342 | F29: =IFERROR('Historical FS'!F6/(('Historical FS'!F64+'Historical FS'!E64)/2),0) -> 0.98616155 | G29: =IFERROR('Historical FS'!G6/(('Historical FS'!G64+'Historical FS'!F64)/2),0) -> 1.0510278 | H29: =IFERROR('Historical FS'!H6/(('Historical FS'!H64+'Historical FS'!G64)/2),0) -> 1.1928253 | I29: =IFERROR('Historical FS'!I6/(('Historical FS'!I64+'Historical FS'!H64)/2),0) -> 1.4391339 | J29: =IFERROR('Historical FS'!J6/(('Historical FS'!J64+'Historical FS'!I64)/2),0) -> 1.7697661 | K29: =IFERROR('Historical FS'!K6/(('Historical FS'!K64+'Historical FS'!J64)/2),0) -> 2.0083949 | ... M29: =IFERROR('Historical FS'!M6/(('Historical FS'!M64+'Historical FS'!L64)/2),0) -> 2.6634892 | O29: =IFERROR(AVERAGE(C29:M29),0) -> 1.3665003 | P29: =IFERROR(MEDIAN(C29:M29),0) -> 1.1928253
B30: Fixed Asset Turnover Ratio | C30: =IFERROR('Historical FS'!C6/'Historical FS'!C57,0) -> 2.4199301 | D30: =IFERROR('Historical FS'!D6/(('Historical FS'!D57+'Historical FS'!C57)/2),0) -> 2.5149172 | E30: =IFERROR('Historical FS'!E6/(('Historical FS'!E57+'Historical FS'!D57)/2),0) -> 2.4832412 | F30: =IFERROR('Historical FS'!F6/(('Historical FS'!F57+'Historical FS'!E57)/2),0) -> 2.6631935 | G30: =IFERROR('Historical FS'!G6/(('Historical FS'!G57+'Historical FS'!F57)/2),0) -> 2.8947009 | H30: =IFERROR('Historical FS'!H6/(('Historical FS'!H57+'Historical FS'!G57)/2),0) -> 3.1511034 | I30: =IFERROR('Historical FS'!I6/(('Historical FS'!I57+'Historical FS'!H57)/2),0) -> 3.5343733 | J30: =IFERROR('Historical FS'!J6/(('Historical FS'!J57+'Historical FS'!I57)/2),0) -> 3.9598391 | K30: =IFERROR('Historical FS'!K6/(('Historical FS'!K57+'Historical FS'!J57)/2),0) -> 4.4772575 | ... M30: =IFERROR('Historical FS'!M6/(('Historical FS'!M57+'Historical FS'!L57)/2),0) -> 9.6254662 | O30: =IFERROR(AVERAGE(C30:M30),0) -> 3.8495811 | P30: =IFERROR(MEDIAN(C30:M30),0) -> 3.1511034
B31: Capital Turnover Ratio | C31: =IFERROR(('Historical FS'!C6)/('Historical FS'!C51+'Historical FS'!C52),0) -> 1.5190258 | D31: =IFERROR(('Historical FS'!D6)/(('Historical FS'!D51+'Historical FS'!D52)+('Historical FS'!C51+'Historical FS'!C52)/2),0) -> 0.99306291 | E31: =IFERROR(('Historical FS'!E6)/(('Historical FS'!E51+'Historical FS'!E52)+('Historical FS'!D51+'Historical FS'!D52)/2),0) -> 1.172818 | F31: =IFERROR(('Historical FS'!F6)/(('Historical FS'!F51+'Historical FS'!F52)+('Historical FS'!E51+'Historical FS'!E52)/2),0) -> 1.1882826 | G31: =IFERROR(('Historical FS'!G6)/(('Historical FS'!G51+'Historical FS'!G52)+('Historical FS'!F51+'Historical FS'!F52)/2),0) -> 1.111749 | H31: =IFERROR(('Historical FS'!H6)/(('Historical FS'!H51+'Historical FS'!H52)+('Historical FS'!G51+'Historical FS'!G52)/2),0) -> 1.0378338 | I31: =IFERROR(('Historical FS'!I6)/(('Historical FS'!I51+'Historical FS'!I52)+('Historical FS'!H51+'Historical FS'!H52)/2),0) -> 0.91100637 | J31: =IFERROR(('Historical FS'!J6)/(('Historical FS'!J51+'Historical FS'!J52)+('Historical FS'!I51+'Historical FS'!I52)/2),0) -> 0.81036718 | K31: =IFERROR(('Historical FS'!K6)/(('Historical FS'!K51+'Historical FS'!K52)+('Historical FS'!J51+'Historical FS'!J52)/2),0) -> 0.74237362 | ... M31: =IFERROR(('Historical FS'!M6)/(('Historical FS'!M51+'Historical FS'!M52)+('Historical FS'!L51+'Historical FS'!L52)/2),0) -> 1.8355233 | O31: =IFERROR(AVERAGE(C31:M31),0) -> 1.0861164 | P31: =IFERROR(MEDIAN(C31:M31),0) -> 1.0378338
B33: Debtors Days | C33: =IFERROR(365/C27:C27,0) -> 105.34764 | D33: =IFERROR(365/D27:D27,0) -> 92.084725 | E33: =IFERROR(365/E27:E27,0) -> 108.11897 | F33: =IFERROR(365/F27:F27,0) -> 175.21697 | G33: =IFERROR(365/G27:G27,0) -> 201.627 | H33: =IFERROR(365/H27:H27,0) -> 134.80964 | I33: =IFERROR(365/I27:I27,0) -> 76.421479 | J33: =IFERROR(365/J27:J27,0) -> 63.441913 | ... M33: =IFERROR(365/M27:M27,0) -> 26.420417 | O33: =IFERROR(AVERAGE(C33:M33),0) -> 99.467811 | P33: =IFERROR(MEDIAN(C33:M33),0) -> 92.084725
B34: Payable Days | C34: =IFERROR(365/C28,0) -> 989.24071 | D34: =IFERROR(365/D28,0) -> 849.79557 | E34: =IFERROR(365/E28,0) -> 750.9941 | F34: =IFERROR(365/F28,0) -> 669.00415 | G34: =IFERROR(365/G28,0) -> 598.4729 | H34: =IFERROR(365/H28,0) -> 579.39805 | I34: =IFERROR(365/I28,0) -> 581.9772 | J34: =IFERROR(365/J28,0) -> 586.54987 | ... M34: =IFERROR(365/M28,0) -> 418.75189 | O34: =IFERROR(AVERAGE(C34:M34),0) -> 667.97655 | P34: =IFERROR(MEDIAN(C34:M34),0) -> 598.4729
B35: Inventory Days | C35: =IFERROR(365/C29,0) -> 522.32124 | D35: =IFERROR(365/D29,0) -> 462.62106 | E35: =IFERROR(365/E29,0) -> 410.43821 | F35: =IFERROR(365/F29,0) -> 370.12191 | G35: =IFERROR(365/G29,0) -> 347.27912 | H35: =IFERROR(365/H29,0) -> 305.99619 | I35: =IFERROR(365/I29,0) -> 253.62476 | J35: =IFERROR(365/J29,0) -> 206.24195 | ... M35: =IFERROR(365/M29,0) -> 137.03829 | O35: =IFERROR(AVERAGE(C35:M35),0) -> 312.17057 | P35: =IFERROR(MEDIAN(C35:M35),0) -> 305.99619
B36: Cash Conversion Cycle | C36: =IFERROR((C33+C35-C34),0) -> -361.57183 | D36: =IFERROR((D33+D35-D34),0) -> -295.08978 | E36: =IFERROR((E33+E35-E34),0) -> -232.43692 | F36: =IFERROR((F33+F35-F34),0) -> -123.66528 | G36: =IFERROR((G33+G35-G34),0) -> -49.566783 | H36: =IFERROR((H33+H35-H34),0) -> -138.59222 | I36: =IFERROR((I33+I35-I34),0) -> -251.93096 | J36: =IFERROR((J33+J35-J34),0) -> -316.86602 | ... M36: =IFERROR((M33+M35-M34),0) -> -255.29319 | O36: =IFERROR(AVERAGE(C36:M36),0) -> -256.33817 | P36: =IFERROR(MEDIAN(C36:M36),0) -> -255.29319
B38: CFO / Sales | C38: =IFERROR('Historical FS'!C72/'Historical FS'!C6,0) -> 0 | D38: =IFERROR('Historical FS'!D72/'Historical FS'!D6,0) -> -0.022534919 | E38: =IFERROR('Historical FS'!E72/'Historical FS'!E6,0) -> -0.040367737 | F38: =IFERROR('Historical FS'!F72/'Historical FS'!F6,0) -> -0.38486006 | G38: =IFERROR('Historical FS'!G72/'Historical FS'!G6,0) -> 0.071223064 | H38: =IFERROR('Historical FS'!H72/'Historical FS'!H6,0) -> 0.66064105 | I38: =IFERROR('Historical FS'!I72/'Historical FS'!I6,0) -> 0.41320559 | J38: =IFERROR('Historical FS'!J72/'Historical FS'!J6,0) -> 0.32790765 | ... M38: =IFERROR('Historical FS'!M72/'Historical FS'!M6,0) -> 0 | O38: =IFERROR(AVERAGE(C38:M38),0) -> 0.15784117 | P38: =IFERROR(MEDIAN(C38:M38),0) -> 0.071223064
B39: CFO / Total Assets | C39: =IFERROR('Historical FS'!C72/'Historical FS'!C68,0) -> 0 | D39: =IFERROR('Historical FS'!D72/'Historical FS'!D68,0) -> -0.0078173768 | E39: =IFERROR('Historical FS'!E72/'Historical FS'!E68,0) -> -0.015426326 | F39: =IFERROR('Historical FS'!F72/'Historical FS'!F68,0) -> -0.14953066 | G39: =IFERROR('Historical FS'!G72/'Historical FS'!G68,0) -> 0.028179244 | H39: =IFERROR('Historical FS'!H72/'Historical FS'!H68,0) -> 0.28470846 | I39: =IFERROR('Historical FS'!I72/'Historical FS'!I68,0) -> 0.16883647 | J39: =IFERROR('Historical FS'!J72/'Historical FS'!J68,0) -> 0.12745713 | ... M39: =IFERROR('Historical FS'!M72/'Historical FS'!M68,0) -> 0 | O39: =IFERROR(AVERAGE(C39:M39),0) -> 0.060322881 | P39: =IFERROR(MEDIAN(C39:M39),0) -> 0.028179244
B40: CFO / Total Debt | C40: =IFERROR('Historical FS'!C72/'Historical FS'!C53,0) -> 0 | D40: =IFERROR('Historical FS'!D72/'Historical FS'!D53,0) -> -0.39578095 | E40: =IFERROR('Historical FS'!E72/'Historical FS'!E53,0) -> -0.82651572 | F40: =IFERROR('Historical FS'!F72/'Historical FS'!F53,0) -> -1.8707254 | G40: =IFERROR('Historical FS'!G72/'Historical FS'!G53,0) -> 0.25770166 | H40: =IFERROR('Historical FS'!H72/'Historical FS'!H53,0) -> 283.72748 | I40: =IFERROR('Historical FS'!I72/'Historical FS'!I53,0) -> 206.47717 | J40: =IFERROR('Historical FS'!J72/'Historical FS'!J53,0) -> 170.82066 | ... M40: =IFERROR('Historical FS'!M72/'Historical FS'!M53,0) -> 0 | O40: =IFERROR(AVERAGE(C40:M40),0) -> 98.862109 | P40: =IFERROR(MEDIAN(C40:M40),0) -> 0.25770166

Sheet Reg Forcast
B1: ='Data Sheet'!$B$1&" - "&" Linear Regression Forecasting" -> HINDUSTAN AERONAUTICS LTD - Linear Regression Forecasting
B2: Year | C2: ='Data Sheet'!B16 -> 42460 | D2: =C2+365 -> 42825 | E2: =D2+365 -> 43190 | F2: =E2+365 -> 43555 | G2: =F2+365 -> 43920 | H2: =G2+365 -> 44285 | I2: =H2+365 -> 44650 | J2: =I2+365 -> 45015 | K2: =J2+365 -> 45380 | ... Q2: =P2+365 -> 47570
B3: Weightage | C3: =1 -> 1 | D3: =C3+1 -> 2 | E3: =D3+1 -> 3 | F3: =E3+1 -> 4 | G3: =F3+1 -> 5 | H3: =G3+1 -> 6 | I3: =H3+1 -> 7 | J3: =I3+1 -> 8 | K3: =J3+1 -> 9 | ... Q3: =P3+1 -> 15
B5: ='Data Sheet'!A17 -> Sales | C5: =IFERROR('Historical FS'!C6,0) -> 16758.5 | D5: =IFERROR('Historical FS'!D6,0) -> 17949.92 | E5: =IFERROR('Historical FS'!E6,0) -> 18519.74 | F5: =IFERROR('Historical FS'!F6,0) -> 20008 | G5: =IFERROR('Historical FS'!G6,0) -> 21445.16 | H5: =IFERROR('Historical FS'!H6,0) -> 22882.32 | I5: =IFERROR('Historical FS'!I6,0) -> 24620.02 | J5: =IFERROR('Historical FS'!J6,0) -> 26927.46 | ... L5: =IFERROR('Historical FS'!L6,0) -> 30980.95 | M5: =_xlfn.FORECAST.LINEAR($M$3,$C$5:$L$5,$C$3:$L$3) -> 32125.048 | N5: =_xlfn.FORECAST.LINEAR(N3,$C$5:$L$5,$C$3:$L$3) -> 33775.545 | O5: =_xlfn.FORECAST.LINEAR(O3,$C$5:$L$5,$C$3:$L$3) -> 35426.042 | P5: =_xlfn.FORECAST.LINEAR(P3,$C$5:$L$5,$C$3:$L$3) -> 37076.539 | Q5: =_xlfn.FORECAST.LINEAR(Q3,$C$5:$L$5,$C$3:$L$3) -> 38727.036
B6: Sales Growth | C6: =IFERROR(C5/C5-1,0) -> 0 | D6: =IFERROR(D5/C5-1,0) -> 0.071093475 | E6: =IFERROR(E5/D5-1,0) -> 0.031744988 | F6: =IFERROR(F5/E5-1,0) -> 0.080360739 | G6: =IFERROR(G5/F5-1,0) -> 0.071829268 | H6: =IFERROR(H5/G5-1,0) -> 0.067015588 | I6: =IFERROR(I5/H5-1,0) -> 0.075940726 | J6: =IFERROR(J5/I5-1,0) -> 0.093722101 | K6: =IFERROR(K5/J5-1,0) -> 0.12825643 | ... Q6: =IFERROR(Q5/P5-1,0) -> 0.044515938
B8: COGS | C8: =IFERROR('Historical FS'!C9,0) -> 12512.9 | D8: =IFERROR('Historical FS'!D9,0) -> 13838.91 | E8: =IFERROR('Historical FS'!E9,0) -> 14219.92 | F8: =IFERROR('Historical FS'!F9,0) -> 14087.52 | G8: =IFERROR('Historical FS'!G9,0) -> 14937.2 | H8: =IFERROR('Historical FS'!H9,0) -> 16337.81 | I8: =IFERROR('Historical FS'!I9,0) -> 15494.02 | J8: =IFERROR('Historical FS'!J9,0) -> 16160.85 | ... L8: =IFERROR('Historical FS'!L9,0) -> 19124.16 | M8: =_xlfn.FORECAST.LINEAR(M3,$C$8:$L$8,$C$3:$L$3) -> 18759.55 | N8: =_xlfn.FORECAST.LINEAR(N3,$C$8:$L$8,$C$3:$L$3) -> 19367.058 | O8: =_xlfn.FORECAST.LINEAR(O3,$C$8:$L$8,$C$3:$L$3) -> 19974.565 | P8: =_xlfn.FORECAST.LINEAR(P3,$C$8:$L$8,$C$3:$L$3) -> 20582.073 | Q8: =_xlfn.FORECAST.LINEAR(Q3,$C$8:$L$8,$C$3:$L$3) -> 21189.581
B9: COGS Growth | C9: =IFERROR(C8/C8-1,0) -> 0 | D9: =IFERROR(D8/C8-1,0) -> 0.10597144 | E9: =IFERROR(E8/D8-1,0) -> 0.027531793 | F9: =IFERROR(F8/E8-1,0) -> -0.0093108822 | G9: =IFERROR(G8/F8-1,0) -> 0.060314378 | H9: =IFERROR(H8/G8-1,0) -> 0.093766569 | I9: =IFERROR(I8/H8-1,0) -> -0.051646457 | J9: =IFERROR(J8/I8-1,0) -> 0.043037895 | K9: =IFERROR(K8/J8-1,0) -> 0.080963563 | ... Q9: =IFERROR(Q8/P8-1,0) -> 0.029516348
B11: Gross Profit | C11: =IFERROR('Historical FS'!C12,0) -> 4245.6 | D11: =IFERROR('Historical FS'!D12,0) -> 4111.01 | E11: =IFERROR('Historical FS'!E12,0) -> 4299.82 | F11: =IFERROR('Historical FS'!F12,0) -> 5920.48 | G11: =IFERROR('Historical FS'!G12,0) -> 6507.96 | H11: =IFERROR('Historical FS'!H12,0) -> 6544.51 | I11: =IFERROR('Historical FS'!I12,0) -> 9126 | J11: =IFERROR('Historical FS'!J12,0) -> 10766.61 | ... L11: =IFERROR('Historical FS'!L12,0) -> 11856.79 | M11: =_xlfn.FORECAST.LINEAR(M3,$C$11:$L$11,$C$3:$L$3) -> 13365.498 | N11: =_xlfn.FORECAST.LINEAR(N3,$C$11:$L$11,$C$3:$L$3) -> 14408.487 | O11: =_xlfn.FORECAST.LINEAR(O3,$C$11:$L$11,$C$3:$L$3) -> 15451.477 | P11: =_xlfn.FORECAST.LINEAR(P3,$C$11:$L$11,$C$3:$L$3) -> 16494.466 | Q11: =_xlfn.FORECAST.LINEAR(Q3,$C$11:$L$11,$C$3:$L$3) -> 17537.455
B12: Gross Profit Growth | C12: =IFERROR(C11/C11-1,0) -> 0 | D12: =IFERROR(D11/C11-1,0) -> -0.031701055 | E12: =IFERROR(E11/D11-1,0) -> 0.045927886 | F12: =IFERROR(F11/E11-1,0) -> 0.37691345 | G12: =IFERROR(G11/F11-1,0) -> 0.099228441 | H12: =IFERROR(H11/G11-1,0) -> 0.0056161992 | I12: =IFERROR(I11/H11-1,0) -> 0.39445123 | J12: =IFERROR(J11/I11-1,0) -> 0.17977318 | K12: =IFERROR(K11/J11-1,0) -> 0.19924377 | ... Q12: =IFERROR(Q11/P11-1,0) -> 0.06323268
B14: Selling & General Expenses | C14: =IFERROR('Historical FS'!C15,0) -> 1771.7 | D14: =IFERROR('Historical FS'!D15,0) -> 880.32 | E14: =IFERROR('Historical FS'!E15,0) -> 851.13 | F14: =IFERROR('Historical FS'!F15,0) -> 1369.45 | G14: =IFERROR('Historical FS'!G15,0) -> 1593.72 | H14: =IFERROR('Historical FS'!H15,0) -> 1200.53 | I14: =IFERROR('Historical FS'!I15,0) -> 3710.63 | J14: =IFERROR('Historical FS'!J15,0) -> 4080.95 | ... L14: =IFERROR('Historical FS'!L15,0) -> 2235.77 | M14: =_xlfn.FORECAST.LINEAR(M3,$C$14:$L$14,$C$3:$L$3) -> 3515.9513 | N14: =_xlfn.FORECAST.LINEAR(N3,$C$14:$L$14,$C$3:$L$3) -> 3776.0441 | O14: =_xlfn.FORECAST.LINEAR(O3,$C$14:$L$14,$C$3:$L$3) -> 4036.1369 | P14: =_xlfn.FORECAST.LINEAR(P3,$C$14:$L$14,$C$3:$L$3) -> 4296.2297 | Q14: =_xlfn.FORECAST.LINEAR(Q3,$C$14:$L$14,$C$3:$L$3) -> 4556.3225
B15: S&G Growth | C15: =IFERROR(C14/C14-1,0) -> 0 | D15: =IFERROR(D14/C14-1,0) -> -0.5031213 | E15: =IFERROR(E14/D14-1,0) -> -0.033158397 | F15: =IFERROR(F14/E14-1,0) -> 0.60897865 | G15: =IFERROR(G14/F14-1,0) -> 0.16376648 | H15: =IFERROR(H14/G14-1,0) -> -0.24671209 | I15: =IFERROR(I14/H14-1,0) -> 2.0908266 | J15: =IFERROR(J14/I14-1,0) -> 0.099799764 | K15: =IFERROR(K14/J14-1,0) -> -0.22561903 | ... Q15: =IFERROR(Q14/P14-1,0) -> 0.060539777
B17: EBITDA | C17: =IFERROR('Historical FS'!C18,0) -> 2473.9 | D17: =IFERROR('Historical FS'!D18,0) -> 3230.69 | E17: =IFERROR('Historical FS'!E18,0) -> 3448.69 | F17: =IFERROR('Historical FS'!F18,0) -> 4551.03 | G17: =IFERROR('Historical FS'!G18,0) -> 4914.24 | H17: =IFERROR('Historical FS'!H18,0) -> 5343.98 | I17: =IFERROR('Historical FS'!I18,0) -> 5415.37 | J17: =IFERROR('Historical FS'!J18,0) -> 6685.66 | ... L17: =IFERROR('Historical FS'!L18,0) -> 9621.02 | M17: =_xlfn.FORECAST.LINEAR(M3,$C$17:$L$17,$C$3:$L$3) -> 9849.5467 | N17: =_xlfn.FORECAST.LINEAR(N3,$C$17:$L$17,$C$3:$L$3) -> 10632.443 | O17: =_xlfn.FORECAST.LINEAR(O3,$C$17:$L$17,$C$3:$L$3) -> 11415.34 | P17: =_xlfn.FORECAST.LINEAR(P3,$C$17:$L$17,$C$3:$L$3) -> 12198.236 | Q17: =_xlfn.FORECAST.LINEAR(Q3,$C$17:$L$17,$C$3:$L$3) -> 12981.133
B18: EBITDA Growth | C18: =IFERROR(C17/C17-1,0) -> 0 | D18: =IFERROR(D17/C17-1,0) -> 0.3059097 | E18: =IFERROR(E17/D17-1,0) -> 0.067477845 | F18: =IFERROR(F17/E17-1,0) -> 0.31964021 | G18: =IFERROR(G17/F17-1,0) -> 0.079808307 | H18: =IFERROR(H17/G17-1,0) -> 0.087447906 | I18: =IFERROR(I17/H17-1,0) -> 0.013358957 | J18: =IFERROR(J17/I17-1,0) -> 0.23457123 | K18: =IFERROR(K17/J17-1,0) -> 0.4585815 | ... Q18: =IFERROR(Q17/P17-1,0) -> 0.064181122
B20: Interest | C20: =IFERROR('Historical FS'!C24,0) -> 5.9 | D20: =IFERROR('Historical FS'!D24,0) -> 16.45 | E20: =IFERROR('Historical FS'!E24,0) -> 34.62 | F20: =IFERROR('Historical FS'!F24,0) -> 177.6 | G20: =IFERROR('Historical FS'!G24,0) -> 359.59 | H20: =IFERROR('Historical FS'!H24,0) -> 266.89 | I20: =IFERROR('Historical FS'!I24,0) -> 65.24 | J20: =IFERROR('Historical FS'!J24,0) -> 64.41 | ... L20: =IFERROR('Historical FS'!L24,0) -> 21.62 | M20: =_xlfn.FORECAST.LINEAR(M3,$C$20:$L$20,$C$3:$L$3) -> 106.95867 | N20: =_xlfn.FORECAST.LINEAR(N3,$C$20:$L$20,$C$3:$L$3) -> 107.22479 | O20: =_xlfn.FORECAST.LINEAR(O3,$C$20:$L$20,$C$3:$L$3) -> 107.49091 | P20: =_xlfn.FORECAST.LINEAR(P3,$C$20:$L$20,$C$3:$L$3) -> 107.75703 | Q20: =_xlfn.FORECAST.LINEAR(Q3,$C$20:$L$20,$C$3:$L$3) -> 108.02315
B21: Interest Growth | C21: =IFERROR(C20/C20-1,0) -> 0 | D21: =IFERROR(D20/C20-1,0) -> 1.7881356 | E21: =IFERROR(E20/D20-1,0) -> 1.1045593 | F21: =IFERROR(F20/E20-1,0) -> 4.1299827 | G21: =IFERROR(G20/F20-1,0) -> 1.0247185 | H21: =IFERROR(H20/G20-1,0) -> -0.2577936 | I21: =IFERROR(I20/H20-1,0) -> -0.75555472 | J21: =IFERROR(J20/I20-1,0) -> -0.012722256 | K21: =IFERROR(K20/J20-1,0) -> -0.33814625 | ... Q21: =IFERROR(Q20/P20-1,0) -> 0.0024696413
B23: Depreciation | C23: =IFERROR('Historical FS'!C27,0) -> 862.8 | D23: =IFERROR('Historical FS'!D27,0) -> 680.68 | E23: =IFERROR('Historical FS'!E27,0) -> 947.09 | F23: =IFERROR('Historical FS'!F27,0) -> 1025.26 | G23: =IFERROR('Historical FS'!G27,0) -> 998.52 | H23: =IFERROR('Historical FS'!H27,0) -> 1157.89 | I23: =IFERROR('Historical FS'!I27,0) -> 1110.53 | J23: =IFERROR('Historical FS'!J27,0) -> 1784.67 | ... L23: =IFERROR('Historical FS'!L27,0) -> 1340.37 | M23: =_xlfn.FORECAST.LINEAR(M3,$C$23:$L$23,$C$3:$L$3) -> 1597.7193 | N23: =_xlfn.FORECAST.LINEAR(N3,$C$23:$L$23,$C$3:$L$3) -> 1682.4868 | O23: =_xlfn.FORECAST.LINEAR(O3,$C$23:$L$23,$C$3:$L$3) -> 1767.2544 | P23: =_xlfn.FORECAST.LINEAR(P3,$C$23:$L$23,$C$3:$L$3) -> 1852.0219 | Q23: =_xlfn.FORECAST.LINEAR(Q3,$C$23:$L$23,$C$3:$L$3) -> 1936.7894
B24: Depreciation Growth | C24: =IFERROR(C23/C23-1,0) -> 0 | D24: =IFERROR(D23/C23-1,0) -> -0.2110802 | E24: =IFERROR(E23/D23-1,0) -> 0.39138802 | F24: =IFERROR(F23/E23-1,0) -> 0.082537034 | G24: =IFERROR(G23/F23-1,0) -> -0.026081189 | H24: =IFERROR(H23/G23-1,0) -> 0.15960622 | I24: =IFERROR(I23/H23-1,0) -> -0.040901986 | J24: =IFERROR(J23/I23-1,0) -> 0.60704348 | K24: =IFERROR(K23/J23-1,0) -> -0.2115237 | ... Q24: =IFERROR(Q23/P23-1,0) -> 0.045770256
B26: Profit Before Tax | C26: =IFERROR('Historical FS'!C30,0) -> 3213.3 | D26: =IFERROR('Historical FS'!D30,0) -> 3591.76 | E26: =IFERROR('Historical FS'!E30,0) -> 3242.68 | F26: =IFERROR('Historical FS'!F30,0) -> 3724.43 | G26: =IFERROR('Historical FS'!G30,0) -> 3978.64 | H26: =IFERROR('Historical FS'!H30,0) -> 4283.48 | I26: =IFERROR('Historical FS'!I30,0) -> 5224.53 | J26: =IFERROR('Historical FS'!J30,0) -> 6509.5 | ... L26: =IFERROR('Historical FS'!L30,0) -> 10867.26 | M26: =_xlfn.FORECAST.LINEAR(M3,$C$26:$L$26,$C$3:$L$3) -> 10034.603 | N26: =_xlfn.FORECAST.LINEAR(N3,$C$26:$L$26,$C$3:$L$3) -> 10861.614 | O26: =_xlfn.FORECAST.LINEAR(O3,$C$26:$L$26,$C$3:$L$3) -> 11688.624 | P26: =_xlfn.FORECAST.LINEAR(P3,$C$26:$L$26,$C$3:$L$3) -> 12515.635 | Q26: =_xlfn.FORECAST.LINEAR(Q3,$C$26:$L$26,$C$3:$L$3) -> 13342.645
B27: PBT Growth | C27: =IFERROR(C26/C26-1,0) -> 0 | D27: =IFERROR(D26/C26-1,0) -> 0.11777923 | E27: =IFERROR(E26/D26-1,0) -> -0.097189122 | F27: =IFERROR(F26/E26-1,0) -> 0.14856538 | G27: =IFERROR(G26/F26-1,0) -> 0.06825474 | H27: =IFERROR(H26/G26-1,0) -> 0.076619146 | I27: =IFERROR(I26/H26-1,0) -> 0.21969287 | J27: =IFERROR(J26/I26-1,0) -> 0.2459494 | K27: =IFERROR(K26/J26-1,0) -> 0.57076273 | ... Q27: =IFERROR(Q26/P26-1,0) -> 0.066078185
B29: Tax | C29: =IFERROR('Historical FS'!C33,0) -> 1209 | D29: =IFERROR('Historical FS'!D33,0) -> 966.95 | E29: =IFERROR('Historical FS'!E33,0) -> 1252.43 | F29: =IFERROR('Historical FS'!F33,0) -> 1396.28 | G29: =IFERROR('Historical FS'!G33,0) -> 1095.99 | H29: =IFERROR('Historical FS'!H33,0) -> 1037.93 | I29: =IFERROR('Historical FS'!I33,0) -> 144.65 | J29: =IFERROR('Historical FS'!J33,0) -> 681.77 | ... L29: =IFERROR('Historical FS'!L33,0) -> 2503.21 | M29: =_xlfn.FORECAST.LINEAR(M3,$C$29:$L$29,$C$3:$L$3) -> 1837.2307 | N29: =_xlfn.FORECAST.LINEAR(N3,$C$29:$L$29,$C$3:$L$3) -> 1936.8701 | O29: =_xlfn.FORECAST.LINEAR(O3,$C$29:$L$29,$C$3:$L$3) -> 2036.5095 | P29: =_xlfn.FORECAST.LINEAR(P3,$C$29:$L$29,$C$3:$L$3) -> 2136.1488 | Q29: =_xlfn.FORECAST.LINEAR(Q3,$C$29:$L$29,$C$3:$L$3) -> 2235.7882
B30: Effective Tax Rate | C30: =IFERROR(C29/C29-1,0) -> 0 | D30: =IFERROR(D29/C29-1,0) -> -0.20020678 | E30: =IFERROR(E29/D29-1,0) -> 0.2952376 | F30: =IFERROR(F29/E29-1,0) -> 0.11485672 | G30: =IFERROR(G29/F29-1,0) -> -0.21506431 | H30: =IFERROR(H29/G29-1,0) -> -0.052974936 | I30: =IFERROR(I29/H29-1,0) -> -0.86063607 | J30: =IFERROR(J29/I29-1,0) -> 3.7132389 | K30: =IFERROR(K29/J29-1,0) -> 2.8193672 | ... Q30: =IFERROR(Q29/P29-1,0) -> 0.046644406
B32: Net Profit | C32: =IFERROR('Historical FS'!C36,0) -> 2004.3 | D32: =IFERROR('Historical FS'!D36,0) -> 2624.81 | E32: =IFERROR('Historical FS'!E36,0) -> 1990.25 | F32: =IFERROR('Historical FS'!F36,0) -> 2328.15 | G32: =IFERROR('Historical FS'!G36,0) -> 2882.65 | H32: =IFERROR('Historical FS'!H36,0) -> 3245.55 | I32: =IFERROR('Historical FS'!I36,0) -> 5079.88 | J32: =IFERROR('Historical FS'!J36,0) -> 5827.73 | ... L32: =IFERROR('Historical FS'!L36,0) -> 8364.05 | M32: =_xlfn.FORECAST.LINEAR(M3,$C$32:$L$32,$C$3:$L$3) -> 8197.3727 | N32: =_xlfn.FORECAST.LINEAR(N3,$C$32:$L$32,$C$3:$L$3) -> 8924.7437 | O32: =_xlfn.FORECAST.LINEAR(O3,$C$32:$L$32,$C$3:$L$3) -> 9652.1147 | P32: =_xlfn.FORECAST.LINEAR(P3,$C$32:$L$32,$C$3:$L$3) -> 10379.486 | Q32: =_xlfn.FORECAST.LINEAR(Q3,$C$32:$L$32,$C$3:$L$3) -> 11106.857
B33: Net Margins | C33: =IFERROR(C32/C32-1,0) -> 0 | D33: =IFERROR(D32/C32-1,0) -> 0.30958938 | E33: =IFERROR(E32/D32-1,0) -> -0.24175464 | F33: =IFERROR(F32/E32-1,0) -> 0.16977767 | G33: =IFERROR(G32/F32-1,0) -> 0.23817194 | H33: =IFERROR(H32/G32-1,0) -> 0.12589111 | I33: =IFERROR(I32/H32-1,0) -> 0.5651831 | J33: =IFERROR(J32/I32-1,0) -> 0.14721804 | K33: =IFERROR(K32/J32-1,0) -> 0.30770472 | ... Q33: =IFERROR(Q32/P32-1,0) -> 0.070077752
B35: ='Historical FS'!B39 -> No. of Equity Shares | C35: ='Historical FS'!C39 -> 72.3 | D35: ='Historical FS'!D39 -> 72.3 | E35: ='Historical FS'!E39 -> 66.88 | F35: ='Historical FS'!F39 -> 66.88 | G35: ='Historical FS'!G39 -> 66.88 | H35: ='Historical FS'!H39 -> 66.88 | I35: ='Historical FS'!I39 -> 66.88 | ... L35: ='Historical FS'!L39 -> 66.88 | M35: =L35 -> 66.88 | N35: =M35 -> 66.88 | O35: =N35 -> 66.88 | P35: =O35 -> 66.88 | Q35: =P35 -> 66.88
B37: ='Historical FS'!B41 -> Earnings Per Share | C37: =IFERROR(C32/C35,0) -> 27.721992 | D37: =IFERROR(D32/D35,0) -> 36.304426 | E37: =IFERROR(E32/E35,0) -> 29.758523 | F37: =IFERROR(F32/F35,0) -> 34.810855 | G37: =IFERROR(G32/G35,0) -> 43.101824 | H37: =IFERROR(H32/H35,0) -> 48.527961 | I37: =IFERROR(I32/I35,0) -> 75.955144 | J37: =IFERROR(J32/J35,0) -> 87.137111 | ... Q37: =IFERROR(Q32/Q35,0) -> 166.07142
B38: ='Historical FS'!B42 -> EPS growth | C38: =C37/C37-1 -> 0 | D38: =IFERROR(D37/C37-1,0) -> 0.30958938 | E38: =IFERROR(E37/D37-1,0) -> -0.18030593 | F38: =IFERROR(F37/E37-1,0) -> 0.16977767 | G38: =IFERROR(G37/F37-1,0) -> 0.23817194 | H38: =IFERROR(H37/G37-1,0) -> 0.12589111 | I38: =IFERROR(I37/H37-1,0) -> 0.5651831 | J38: =IFERROR(J37/I37-1,0) -> 0.14721804 | K38: =IFERROR(K37/J37-1,0) -> 0.30770472 | ... Q38: =IFERROR(Q37/P37-1,0) -> 0.070077752

Sheet Wacc
B2: Weighted Average Cost of Capital
B4: All figures are in INR unless stated otherwise
B5: Peer Comps
H6: Debt / | I6: Debt / | J6: Levered | K6: Unlevered
B7: Name of the Comp | D7: Country | E7: Total Debt | F7: Total Equity | G7: Tax Rate 1 | H7: Equity | I7: Capital | J7: Beta 2 | K7: Beta 3
B10: ='Peer data'!C3 -> Hind.Aeronautics | D10: India | E10: ='Peer data'!F3 -> 11.4 | F10: ='Peer data'!J3 -> 334.39 | G10: 0.3 | H10: =E10/F10 -> 0.034091929 | I10: =E10/(E10+F10) -> 0.032967986 | J10: =Beta!M8 -> 1.6170793 | K10: =J10/(1+(1-G10)*H10) -> 1.5793882
B11: ='Peer data'!C4 -> Bharat Electron | D11: India | E11: ='Peer data'!F4 -> 58.89 | F11: ='Peer data'!J4 -> 730.98 | G11: 0.3 | H11: =E11/F11 -> 0.08056308 | I11: =E11/(E11+F11) -> 0.074556573 | J11: =Beta!AI8 -> 1.2462382 | K11: =J11/(1+(1-G11)*H11) -> 1.1797095
B12: ='Peer data'!C5 -> Bharat Dynamics | D12: India | E12: ='Peer data'!F5 -> 1.24 | F12: ='Peer data'!J5 -> 182.38 | G12: 0.3 | H12: =E12/F12 -> 0.0067989911 | I12: =E12/(E12+F12) -> 0.006753077 | J12: =Beta!BD8 -> 1.466286 | K12: =J12/(1+(1-G12)*H12) -> 1.4593405
B13: ='Peer data'!C6 -> Data Pattern | D13: India | E13: ='Peer data'!F6 -> 5.81 | F13: ='Peer data'!J6 -> 11.2 | G13: 0.3 | H13: =E13/F13 -> 0.51875 | I13: =E13/(E13+F13) -> 0.34156379 | J13: =Beta!BX8 -> 1.8927246 | K13: =J13/(1+(1-G13)*H13) -> 1.3885187
B14: ='Peer data'!C7 -> Zen Technologies | D14: India | E14: ='Peer data'!F7 -> 17.95 | F14: ='Peer data'!J7 -> 9.03 | G14: 0.3 | H14: =E14/F14 -> 1.9878184 | I14: =E14/(E14+F14) -> 0.66530764 | J14: =Beta!CR8 -> 0.97933055 | K14: =J14/(1+(1-G14)*H14) -> 0.40950937
F16: Average | G16: =AVERAGE(G10:G14) -> 0.3 | H16: =AVERAGE(H10:H14) -> 0.52560448 | I16: =AVERAGE(I10:I14) -> 0.22422981 | J16: =AVERAGE(J10:J14) -> 1.4403317 | K16: =AVERAGE(K10:K14) -> 1.2032933
F17: Median | G17: =MEDIAN(G10:G14) -> 0.3 | H17: =MEDIAN(H10:H14) -> 0.08056308 | I17: =MEDIAN(I10:I14) -> 0.074556573 | J17: =MEDIAN(J10:J14) -> 1.466286 | K17: =MEDIAN(K10:K14) -> 1.3885187
B20: Cost Of Debt | G20: Cost Of Equity
B22: Pre Tax Cost Of Debt | E22: =IFERROR('Data Sheet'!K27/'Data Sheet'!K59,0) -> 0.42029549 | G22: Risk Free Rate | K22: 0.0653
B23: Tax Rate | E23: =30% -> 0.3 | G23: Equity Risk Premium | K23: 0.088
B24: Post Tax Cost of Debt | E24: =E22*(1-E23) -> 0.29420684 | G24: Levered Beta 4 | K24: =K33 -> 1.6694564
G25: Cost Of Equity | K25: =K22+(K23*K24) -> 0.21221217
B28: Capital Structure | G28: Levered Beta
D30: Current | E30: Target | G30: Comps Median Unlevered Beta | K30: =K17 -> 1.3885187
B31: Total Debt | C31: =E10 -> 11.4 | D31: =C31/$C$33 -> 0.032967986 | E31: =I16 -> 0.22422981 | G31: Target Debt / Equity | K31: =E35 -> 0.28904154
B32: Market Capitalization | C32: =F10 -> 334.39 | D32: =C32/$C$33 -> 0.96703201 | E32: =E33-E31 -> 0.77577019 | G32: Tax Rate | K32: =E23 -> 0.3
B33: Total Capital | C33: =SUM(C31:C32) -> 345.79 | D33: =C33/$C$33 -> 1 | E33: =D33 -> 1 | G33: Levered Beta | K33: =K30*(1+(1-K32)*K31) -> 1.6694564
B35: Debt / Equity | D35: =D31/D32 -> 0.034091929 | E35: =E31/E32 -> 0.28904154 | G35: Weighted Average Cost of Capital
B37: Notes : | G37: Cost of Equity | K37: =K25 -> 0.21221217
B38: 1) Tax Rate considered as Marginal Tax Rate for the country | G38: Equity Weight | K38: =E32 -> 0.77577019
B39: 2) Levered Beta is based on 5-year monthly data
B40: 3) Unlevereed Beta = Levered Beta / (1+(1-Tax rate)*Debt/Equity) | G40: Cost of Debt | K40: =E24 -> 0.29420684
B41: 4) Levereed Beta = Unlevered Beta *(1+(1-Tax rate)*Debt/Equity) | G41: Debt Weight | K41: =E31 -> 0.22422981
G43: WACC | K43: =(K37*K38)+(K40*K41) -> 0.23059782

Sheet Intrinsic Growth
B2: Calculation Of ROIC | E2: 44256 | F2: 44621 | G2: 44986 | H2: 45352 | I2: 45717
B4: Current Assets
B5: ='Raw FS'!B31 -> Inventories | E5: =VLOOKUP($B5,'Raw FS'!$B$2:$G$36,2,0) -> 18005 | F5: =VLOOKUP($B5,'Raw FS'!$B$2:$G$36,3,0) -> 16210 | G5: =VLOOKUP($B5,'Raw FS'!$B$2:$G$36,4,0) -> 14221 | H5: =VLOOKUP($B5,'Raw FS'!$B$2:$G$36,5,0) -> 16033 | I5: =VLOOKUP($B5,'Raw FS'!$B$2:$G$36,6,0) -> 24107
B6: ='Raw FS'!B32 -> Trade receivables | E6: =VLOOKUP($B6,'Raw FS'!$B$2:$G$36,2,0) -> 5668 | F6: =VLOOKUP($B6,'Raw FS'!$B$2:$G$36,3,0) -> 4642 | G6: =VLOOKUP($B6,'Raw FS'!$B$2:$G$36,4,0) -> 4719 | H6: =VLOOKUP($B6,'Raw FS'!$B$2:$G$36,5,0) -> 4617 | I6: =VLOOKUP($B6,'Raw FS'!$B$2:$G$36,6,0) -> 4648
B7: ='Raw FS'!B34 -> Loans n Advances | E7: =VLOOKUP($B7,'Raw FS'!$B$2:$G$36,2,0) -> 951 | F7: =VLOOKUP($B7,'Raw FS'!$B$2:$G$36,3,0) -> -962 | G7: =VLOOKUP($B7,'Raw FS'!$B$2:$G$36,4,0) -> -1093 | H7: =VLOOKUP($B7,'Raw FS'!$B$2:$G$36,5,0) -> -41 | I7: =VLOOKUP($B7,'Raw FS'!$B$2:$G$36,6,0) -> -186
B8: ='Raw FS'!B35 -> Other asset items | E8: =VLOOKUP($B8,'Raw FS'!$B$2:$G$36,2,0) -> 11058 | F8: =VLOOKUP($B8,'Raw FS'!$B$2:$G$36,3,0) -> 15416 | G8: =VLOOKUP($B8,'Raw FS'!$B$2:$G$36,4,0) -> 20935 | H8: =VLOOKUP($B8,'Raw FS'!$B$2:$G$36,5,0) -> 23049 | I8: =VLOOKUP($B8,'Raw FS'!$B$2:$G$36,6,0) -> 30424
B9: Total Current Assets | E9: =SUM(E5:E8) -> 35682 | F9: =SUM(F5:F8) -> 35306 | G9: =SUM(G5:G8) -> 38782 | H9: =SUM(H5:H8) -> 43658 | I9: =SUM(I5:I8) -> 58993
B11: Current Liabilities
B12: Trade Payables | E12: =VLOOKUP($B12,'Raw FS'!$B$2:$G$36,2,0) -> 2256 | F12: =VLOOKUP($B12,'Raw FS'!$B$2:$G$36,3,0) -> 2558 | G12: =VLOOKUP($B12,'Raw FS'!$B$2:$G$36,4,0) -> 3135 | H12: =VLOOKUP($B12,'Raw FS'!$B$2:$G$36,5,0) -> 3413 | I12: =VLOOKUP($B12,'Raw FS'!$B$2:$G$36,6,0) -> 5106
B13: Advance from Customers | E13: =VLOOKUP($B13,'Raw FS'!$B$2:$G$36,2,0) -> 16553 | F13: =VLOOKUP($B13,'Raw FS'!$B$2:$G$36,3,0) -> 4352 | G13: =VLOOKUP($B13,'Raw FS'!$B$2:$G$36,4,0) -> 5540 | H13: =VLOOKUP($B13,'Raw FS'!$B$2:$G$36,5,0) -> 7363 | I13: =VLOOKUP($B13,'Raw FS'!$B$2:$G$36,6,0) -> 9789
